Workbook

Sheet Instrucciones
A1: Libro de trabajo de la AE2 y la AE4 · Proyecto Final de Grado 2026 · versión v7 (30/10/2026)
A2: Universidad de la Cuenca del Plata · Ingeniería en Sistemas de Información · Comisión A · Sede Posadas · Docente Titular: PosDr. Darío Ezequiel Díaz · ISI-PFG-2026C2-AE2-v02
A4: Para qué sirve este libro | B4: Reúne, en un solo archivo versionable, los instrumentos de la Unidad Dos que producen el Capítulo III y alimentan los Capítulos V y X: el catálogo de requisitos, la matriz de trazabilidad, el filtro de entidades, el registro de reglas, el glosario, el plan de iteraciones y el dimensionamiento de recursos. La hoja «Panel» controla sola el estado de completitud y avisa qué falta.
A5: Dónde se guarda | B5: En el repositorio del equipo, carpeta /03-requisitos, con la nomenclatura de la cátedra: AAAAMMDD_CatalogoRequisitos_Equipo_vN.xlsx. Se versiona cada vez que se cierra un bloque de filas, no una sola vez antes de la entrega.
A6: Qué celdas se completan | B6: Todas las celdas blancas y grises de cada hoja, a partir de la fila 5. Las filas sombreadas en ocre son ejemplos resueltos sobre el caso conductor «Santa Ana»: se leen, no se copian, y se borran antes de entregar. Las columnas de control, sombreadas en amarillo, contienen fórmulas: no se escriben.
A7: Cómo se usan las listas desplegables | B7: Las columnas de tipo, prioridad y estado admiten sólo los valores de la lista. Si un valor es rechazado, es porque la categoría no corresponde a la clasificación de la cátedra.
A8: Qué mira la corrección | B8: Que cada requisito tenga sus seis campos, que su criterio de aceptación sea un procedimiento ejecutable por un tercero, que la trazabilidad cierre en doble vía y que el conjunto de los requisitos «Must» coincida con el producto mínimo viable del apartado V.5.
A9: Orden de trabajo sugerido | B9: 1) Entidades y Reglas, en el taller. 2) Trazabilidad, con los hallazgos de la AE1 codificados H-01, H-02… 3) Catálogo, derivando requisitos de esos hallazgos. 4) Sesión de validación con el referente y actualización de los estados. 5) Iteraciones y Recursos, ya con el catálogo cerrado.
A10: Advertencia | B10: Ante divergencia entre este libro y la Consigna ISI-PFG-2026C2-AE2-v02, prevalece la consigna. Ante divergencia entre la consigna y la Resolución Rectoral UCP N.º 97/23, prevalece la Resolución.
A12: Leyenda de colores
A13: Ocre | B13: Fila de ejemplo resuelta sobre el caso «Santa Ana». Se borra antes de entregar.
A14: Amarillo | B14: Celda con fórmula de control. No se escribe.
A15: Blanco y gris | B15: Celdas que completa el equipo.
A17: Novedades de la v7 | B17: Se agregan 27 requisitos, las reglas R-08 a R-21, los límites L-07 a L-10, 14 entidades y tres hojas: «Código y pruebas», «Funciones de apoyo y deuda» y «Cambios v7». El detalle está en «Cambios v7».
A18: Requisitos «EXTRA» | B18: Un requisito cuyo origen empieza con «EXTRA» se construyó sin un hallazgo de la AE1. Se declara así para no inventar evidencia. Todos están en estado «Pendiente» hasta que la propietaria los confirme.
A19: Estado de las brechas | B19: En «Código y pruebas», una brecha «Abierta» se cierra con código o se acepta y se declara. «Aceptada y declarada» exige que figure en el informe.

Sheet Catálogo
A1: Catálogo de requisitos · apartado III.5 del informe
A2: Una fila por requisito, con los seis campos completos. Regla de cómputo: un requisito sin criterio de aceptación comprobable no se computa, por bien redactado que esté. Antes de cerrar una fila, aplique la prueba del compañero: otro integrante debe poder decir, en diez segundos, cómo verificaría el requisito.
A4: ID | B4: Enunciado | C4: Tipo | D4: Categoría (si es no funcional) | E4: Prioridad | F4: Motivo de la prioridad | G4: Criterio de aceptación (condición, acción, resultado con valores) | H4: Trazabilidad (H-xx o acta) | I4: Estado de validación | J4: Iteración prevista | K4: ¿Integra el MVP? | L4: Control de completitud
A5: RF-01 | B5: El sistema rechaza la confirmación de la reserva de un turno cuando la profesional seleccionada ya tiene otro turno activo (no cancelado ni cancelado por inasistencia) el mismo día y a la misma hora de inicio, y no acepta reservas fuera de las franjas de atención que cada profesional define. Las franjas se arman en bloques que no se pisen: el sistema compara la hora de inicio y no detecta solapamientos por duración (aceptado por la propietaria el 30/10/2026). | C5: Funcional | E5: Must | F5: Es el «primer requisito derivado» explícito del informe (Cap. I.3) y la condición central de éxito del proyecto: reducir a 0 las superposiciones de turno. | G5: Dado un turno ya confirmado para la profesional X el día D a las H, cuando otra clienta intenta reservar a la misma profesional X, el mismo día D y la misma hora H, el sistema rechaza la reserva y no la registra en la base, verificable repitiendo la reserva y consultando la tabla de turnos. Además, dada una profesional con una franja de 09:00 a 13:00, cuando una clienta intenta reservarle un turno a las 14:00, el sistema responde error 400 OUT_OF_HOURS y no crea el turno; y ante la misma hora ya ocupada responde 409 PROFESSIONAL_SLOT_TAKEN. Verificable con appointments.booking y appointments.out-of-hours. | H5: H-01, H-02; constancia de Loren del 30/10/2026 (pregunta 3) | I5: Validado | J5: 1 | K5: Sí | L5: =IF($A5="","",IF(COUNTBLANK($B5:$C5)+COUNTBLANK($E5:$H5)>0,"Faltan campos",IF(AND($C5="No funcional",$D5=""),"Falta categoría",IF($K5="","Falta definir si integra el MVP","Fila completa")))) -> Fila completa
A6: RF-02 | B6: El sistema permite a una visitante reservar un turno mediante un formulario web, dando de alta su propia cuenta con nombre, apellido y teléfono celular. | C6: Funcional | E6: Must | F6: Es el mecanismo que reemplaza la coordinación por WhatsApp y cuaderno físico, causa raíz identificada del problema (Cap. I.1, I.3). | G6: Dado un visitante sin cuenta, cuando completa el formulario con nombre, apellido y teléfono celular (los tres obligatorios y en campos separados) y elige servicio y horario, el sistema crea la cuenta y el turno queda confirmado y se muestra como «Pendiente de seña» (estado derivado de una seña sin pagar) hasta que la seña se pague, verificable en el listado de turnos de la clienta. | H6: H-04 | I6: Validado | J6: 1 | K6: Sí | L6: =IF($A6="","",IF(COUNTBLANK($B6:$C6)+COUNTBLANK($E6:$H6)>0,"Faltan campos",IF(AND($C6="No funcional",$D6=""),"Falta categoría",IF($K6="","Falta definir si integra el MVP","Fila completa")))) -> Fila completa
A7: RF-03 | B7: El sistema calcula la seña según el valor que la propietaria define en Configuración (un monto fijo en pesos o un porcentaje del servicio; hoy $5.000 ARS) y permite pagarla con Mercado Pago (hoy en modo prueba, con tarjeta de prueba) o coordinarla por WhatsApp; el turno queda confirmado con la seña pendiente hasta que se acredita o la propietaria la marca como pagada. Si la seña no se paga en el plazo definido en RF-14, el turno se libera. | C7: Funcional | E7: Must | F7: Objetivo específico N.º 3 del proyecto (Cap. I.2): reemplaza el cobro manual de señas por transferencia que relevó H-08. El monto lo decide la propietaria, que hoy cobra $5.000. | G7: Dado un turno de precio P y una seña configurada en $5.000, cuando la clienta confirma la reserva y elige Mercado Pago, el sistema genera el cobro por el monto configurado; el turno queda confirmado con la seña «pendiente» y esta pasa a «pagada» cuando la pasarela acredita el pago. Si elige coordinar por WhatsApp, la seña queda «pendiente» hasta que la propietaria la marca como pagada. Verificable en el estado de pago del turno y en el valor de la seña de Configuración. | H7: H-08; constancia de Loren del 30/10/2026 (pregunta 7) | I7: Validado | J7: 2 | K7: Sí | L7: =IF($A7="","",IF(COUNTBLANK($B7:$C7)+COUNTBLANK($E7:$H7)>0,"Faltan campos",IF(AND($C7="No funcional",$D7=""),"Falta categoría",IF($K7="","Falta definir si integra el MVP","Fila completa")))) -> Fila completa
A8: RF-04 | B8: El sistema devuelve el 100% de la seña si la clienta cancela con 12 horas o más de anticipación al turno, y retiene el 100% si cancela con menos de 12 horas o no se presenta. | C8: Funcional | E8: Must | F8: Regla de negocio explícita relevada en la entrevista a la propietaria (R-02); condiciona la confianza de las clientas en el cobro de señas. | G8: Dado un turno con seña pagada, pactado a las 18:00 h del día D, cuando la clienta cancela a las 05:00 h del mismo día D (menos de 12 horas antes), la seña no cambia de estado y queda a favor del estudio (retenida); cuando cancela un día antes a las 17:00 h (más de 12 horas antes), el sistema marca la seña como «devuelta» (estado de pago refunded), verificable en el estado de pago del turno. El sistema solo registra la marca: la devolución del dinero se coordina fuera de él (ver L-08). | H8: H-09; constancia de Loren del 30/10/2026 (pregunta 5) | I8: Validado | J8: 2 | K8: Sí | L8: =IF($A8="","",IF(COUNTBLANK($B8:$C8)+COUNTBLANK($E8:$H8)>0,"Faltan campos",IF(AND($C8="No funcional",$D8=""),"Falta categoría",IF($K8="","Falta definir si integra el MVP","Fila completa")))) -> Fila completa
A9: RF-05 | B9: El sistema cancela automáticamente un turno y libera el horario para reasignar si transcurren más de 20 minutos desde la hora pactada sin que se registre su llegada (la clienta o el personal la registran el día del turno). | C9: Funcional | E9: Should | F9: Evita demoras en la agenda subsiguiente (Cap. I.6), pero no es indispensable para el objetivo central de eliminar superposiciones. | G9: Dado un turno pactado a las 10:00 h, cuando el reloj del sistema marca las 10:21 h sin registro de llegada de la clienta, el turno pasa a estado «cancelado por inasistencia» (cancelled_no_show) y el horario queda disponible para nueva reserva; a las 10:19 h el turno no se modifica. Verificable en el estado del turno y en la grilla de disponibilidad (appointments.arrival-noshow). | H9: H-10; constancia de Loren del 30/10/2026 (pregunta 6) | I9: Validado | J9: 3 | K9: No | L9: =IF($A9="","",IF(COUNTBLANK($B9:$C9)+COUNTBLANK($E9:$H9)>0,"Faltan campos",IF(AND($C9="No funcional",$D9=""),"Falta categoría",IF($K9="","Falta definir si integra el MVP","Fila completa")))) -> Fila completa
A10: RF-06 | B10: Cuando la clienta no indica preferencia por una profesional, el sistema asigna automáticamente el turno a la profesional disponible en ese día y hora, habilitada para el servicio, con menos turnos en la semana; a igual carga, la de mayor antigüedad. | C10: Funcional | E10: Should | F10: Mejora la distribución de la carga de trabajo (Cap. I.6), pero la clienta puede igualmente elegir profesional de forma manual, por lo que no bloquea el objetivo central. | G10: Dadas tres profesionales habilitadas para «manicura» y libres a la hora pedida, con 8, 5 y 5 turnos reservados en la semana, cuando una clienta reserva «manicura» sin elegir profesional, el sistema asigna el turno a la de mayor antigüedad entre las dos con 5 turnos, verificable en el campo de profesional asignada del turno creado. | H10: H-11; constancia de Loren del 30/10/2026 (pregunta 4) | I10: Validado | J10: 3 | K10: No | L10: =IF($A10="","",IF(COUNTBLANK($B10:$C10)+COUNTBLANK($E10:$H10)>0,"Faltan campos",IF(AND($C10="No funcional",$D10=""),"Falta categoría",IF($K10="","Falta definir si integra el MVP","Fila completa")))) -> Fila completa
A11: RF-07 | B11: El sistema solicita un consentimiento diferenciado y específico antes de guardar cualquier dato de alergias o sensibilidad de piel de la clienta, e impide su guardado si no se otorga. | C11: Funcional | E11: Must | F11: Exigencia directa de la Ley N.º 25.326 relevada en Cap. I.6 y I.7; su incumplimiento expone legalmente al proyecto. | G11: Dado el formulario de detalles de la reserva con el campo «alergias» completado, cuando la clienta no marca la casilla de consentimiento, el sistema no guarda ese valor en la base; cuando sí la marca, el valor se guarda junto con la fecha y hora del consentimiento, verificable en el registro de la reserva. Además, ni la propietaria desde el panel ni la profesional pueden cargar o modificar alergias: solo la clienta, con su consentimiento; un intento de cambiarlas desde el panel de administración responde error de validación, verificable con una llamada a la API de administración. | H11: H-13, H-14; constancia de Loren del 30/10/2026 (pregunta 8) | I11: Validado | J11: 2 | K11: Sí | L11: =IF($A11="","",IF(COUNTBLANK($B11:$C11)+COUNTBLANK($E11:$H11)>0,"Faltan campos",IF(AND($C11="No funcional",$D11=""),"Falta categoría",IF($K11="","Falta definir si integra el MVP","Fila completa")))) -> Fila completa
A12: RF-08 | B12: El sistema expone la política de privacidad a la clienta antes de registrar cualquier dato personal, impide continuar el flujo si la rechaza, y registra fecha, hora y versión aceptada. | C12: Funcional | E12: Must | F12: Exigencia de los Art. 21 y 25 de la Ley N.º 25.326 (Cap. I.6, I.7). | G12: Dado un nuevo registro de clienta, cuando no acepta la política de privacidad, el formulario no avanza al paso siguiente; cuando la acepta, el sistema graba fecha, hora y número de versión de la política en el registro del usuario, verificable en la base. | H12: H-15 | I12: Validado | J12: 1 | K12: Sí | L12: =IF($A12="","",IF(COUNTBLANK($B12:$C12)+COUNTBLANK($E12:$H12)>0,"Faltan campos",IF(AND($C12="No funcional",$D12=""),"Falta categoría",IF($K12="","Falta definir si integra el MVP","Fila completa")))) -> Fila completa
A13: RF-09 | B13: El sistema permite a la propietaria ejecutar la anonimización del nombre, el apellido, el correo y el teléfono de una clienta que lo solicite, desactivar su cuenta y cerrar sus sesiones, preservando los turnos y pagos exigidos por obligaciones contables o fiscales, y deja constancia de auditoría. Los demás datos de la clienta (alergias, observaciones, notas, fecha de nacimiento y fotos) quedan fuera de esta versión (ver L-07). | C13: Funcional | E13: Should | F13: Exigencia legal (Cap. I.6, Art. 25 Ley N.º 25.326), pero de volumen de uso bajo esperado en esta primera etapa; no bloquea el objetivo central del proyecto. | G13: Dada una clienta que solicita la baja de sus datos, cuando la propietaria confirma la anonimización desde el panel, el nombre, el apellido y el contacto de la clienta dejan de ser recuperables en las consultas del sistema, y se genera un registro con fecha, hora, usuario que la ejecutó y clienta afectada en el log de auditoría, verificable en ambas consultas. | H13: H-16 | I13: Pendiente | J13: 4 | K13: No | L13: =IF($A13="","",IF(COUNTBLANK($B13:$C13)+COUNTBLANK($E13:$H13)>0,"Faltan campos",IF(AND($C13="No funcional",$D13=""),"Falta categoría",IF($K13="","Falta definir si integra el MVP","Fila completa")))) -> Fila completa
A14: RF-10 | B14: El sistema permite reservar, dentro de un mismo turno, dos o más servicios a cargo de profesionales distintas de forma coordinada, con una sola seña para todos los servicios y todas las profesionales, sin requerir coordinación manual entre ellas. | C14: Funcional | E14: Should | F14: Reduce una coordinación hoy manual y verbal (Anexo I), pero afecta a una porción acotada de las reservas frente al volumen total. | G14: Dada una clienta que reserva «uñas + cejas» para el mismo horario, cuando confirma la reserva, el sistema crea los turnos vinculados —uno por profesional— con el mismo horario de inicio y cobra una sola seña por el combo, verificable en el campo de agrupación de los turnos y en que la seña se registra una única vez. | H14: H-17 | I14: Validado | J14: 3 | K14: No | L14: =IF($A14="","",IF(COUNTBLANK($B14:$C14)+COUNTBLANK($E14:$H14)>0,"Faltan campos",IF(AND($C14="No funcional",$D14=""),"Falta categoría",IF($K14="","Falta definir si integra el MVP","Fila completa")))) -> Fila completa
A15: RF-11 | B15: El sistema centraliza en un catálogo único los servicios ofrecidos, organizados en las categorías uñas, cabello, cuerpo y rostro, cada uno con su precio y duración. | C15: Funcional | E15: Must | F15: Objetivo específico N.º 1 del proyecto (centralizar la información hoy dispersa); sin catálogo no hay reserva posible. | G15: Dado el panel de administración, cuando la propietaria da de alta un servicio con nombre, categoría, precio y duración, el servicio queda disponible para ser elegido por las clientas en el flujo de reserva, verificable en el listado público de servicios. | H15: H-04, H-19 | I15: Validado | J15: 1 | K15: Sí | L15: =IF($A15="","",IF(COUNTBLANK($B15:$C15)+COUNTBLANK($E15:$H15)>0,"Faltan campos",IF(AND($C15="No funcional",$D15=""),"Falta categoría",IF($K15="","Falta definir si integra el MVP","Fila completa")))) -> Fila completa
A16: RF-12 | B16: El sistema registra, en la reserva de una clienta menor de 13 años gestionada por la cuenta de su madre, padre o tutor, únicamente la condición de acompañante y su vínculo, sin ningún dato identificatorio de la menor. | C16: Funcional | E16: Must | F16: Exigencia directa del principio de minimización de datos bajo la Ley N.º 25.326 (Cap. I.7); su incumplimiento expone legalmente al proyecto frente al tratamiento de datos de menores. | G16: Dada una reserva gestionada por una cuenta adulta que marca «acompañante: sí» y elige el vínculo «hija/hijo», cuando se guarda el turno, el sistema registra solo la condición de acompañante y el vínculo de una lista cerrada (hija/hijo, pareja, familiar, amiga/o, otra), sin ningún campo de nombre, edad ni documento de la menor, verificable en el esquema de datos del turno y en el formulario resultante. | H16: H-20; constancia de Loren del 30/10/2026 (pregunta 9) | I16: Validado | J16: 2 | K16: Sí | L16: =IF($A16="","",IF(COUNTBLANK($B16:$C16)+COUNTBLANK($E16:$H16)>0,"Faltan campos",IF(AND($C16="No funcional",$D16=""),"Falta categoría",IF($K16="","Falta definir si integra el MVP","Fila completa")))) -> Fila completa
A17: RNF-01 | B17: El flujo de reserva web (selección de servicio, horario y confirmación) responde en dispositivos móviles con conexión 4G en 5 segundos o menos entre la selección del horario y la confirmación de la reserva, sin esperar la respuesta manual del estudio. | C17: No funcional | D17: Rendimiento | E17: Must | F17: Cap. II.5 (PESTEL social) exige explícitamente un «flujo ultrarrápido y responsivo para dispositivos móviles» dado el volumen de ~450 turnos mensuales. | G17: En una prueba de reserva de punta a punta desde un dispositivo móvil con conexión 4G, el tiempo entre la selección del horario y la confirmación de la reserva (previo a la redirección a la pasarela de pago) es menor o igual a 5 segundos, medido en tres repeticiones consecutivas. | H17: H-06, H-07 | I17: Pendiente | J17: 2 | K17: Sí | L17: =IF($A17="","",IF(COUNTBLANK($B17:$C17)+COUNTBLANK($E17:$H17)>0,"Faltan campos",IF(AND($C17="No funcional",$D17=""),"Falta categoría",IF($K17="","Falta definir si integra el MVP","Fila completa")))) -> Fila completa
A18: RNF-02 | B18: El sistema debe operar íntegramente desde el navegador web, sin exigir a la clienta la descarga de una aplicación nativa para reservar un turno. | C18: No funcional | D18: Usabilidad | E18: Must | F18: Preferencia relevada explícitamente en las conclusiones del relevamiento (Cap. II.6) y en la entrevista a la clienta frecuente. | G18: Un usuario sin ninguna aplicación instalada además del navegador completa el flujo completo de reserva y pago de seña únicamente accediendo a la URL del sistema, verificable repitiendo la prueba en un dispositivo sin instalaciones adicionales. | H18: H-18 | I18: Validado | J18: 1 | K18: Sí | L18: =IF($A18="","",IF(COUNTBLANK($B18:$C18)+COUNTBLANK($E18:$H18)>0,"Faltan campos",IF(AND($C18="No funcional",$D18=""),"Falta categoría",IF($K18="","Falta definir si integra el MVP","Fila completa")))) -> Fila completa
A19: RNF-03 | B19: El sistema muestra la alergia o sensibilidad de piel declarada en un turno solo a la profesional asignada a ese turno, a la propia clienta y a la propietaria; la alergia guardada en el perfil de la clienta la ven además las profesionales que ya la atendieron. Una profesional que nunca atendió a la clienta no ve ninguna. El dato se trata como advertencia operativa, no como historia clínica. | C19: No funcional | D19: Seguridad | E19: Must | F19: Exigencia normativa directa de la Ley N.º 25.326 (Cap. I.6, I.7, II.5). | G19: Dada una clienta con una alergia registrada en un turno y en su perfil, cuando consulta el sistema la profesional asignada al turno, ve ambas; cuando consulta una profesional que atendió antes a la clienta pero no está asignada a ese turno, ve solo la del perfil y recibe error 404 al abrir el turno; cuando consulta una profesional que nunca la atendió, no ve ninguna. Verificable con las pruebas automatizadas de visibilidad y revisando las consultas de cada rol. | H19: H-13, H-14 | I19: Validado | J19: 2 | K19: Sí | L19: =IF($A19="","",IF(COUNTBLANK($B19:$C19)+COUNTBLANK($E19:$H19)>0,"Faltan campos",IF(AND($C19="No funcional",$D19=""),"Falta categoría",IF($K19="","Falta definir si integra el MVP","Fila completa")))) -> Fila completa
A20: RNF-04 | B20: El sistema delega en una pasarela de pagos certificada toda captura de medios de pago y conserva únicamente el identificador de confirmación (token) que ella devuelve; no almacena datos de tarjetas ni de cuentas bancarias. | C20: No funcional | D20: Cumplimiento normativo | E20: Must | F20: Exigencia explícita de Cap. I.7 / II.5 sobre la relación con la pasarela de pagos; evita exponer a Loren y Kologic a responsabilidad sobre datos financieros de terceros. | G20: Una revisión del esquema de la base de datos del sistema no encuentra ninguna columna que almacene número de tarjeta, código de seguridad o dato bancario de la clienta; el único dato de pago retenido es el identificador de confirmación (token) devuelto por la pasarela, verificable por inspección del esquema. | H20: H-08 | I20: Validado | J20: 2 | K20: Sí | L20: =IF($A20="","",IF(COUNTBLANK($B20:$C20)+COUNTBLANK($E20:$H20)>0,"Faltan campos",IF(AND($C20="No funcional",$D20=""),"Falta categoría",IF($K20="","Falta definir si integra el MVP","Fila completa")))) -> Fila completa
A21: RNF-05 | B21: El sistema registra, con fecha y hora, los cambios de estado de un turno y toda anonimización de datos personales; no elimina datos físicamente. | C21: No funcional | D21: Cumplimiento normativo | E21: Should | F21: Exigencia del Art. 25 de la Ley N.º 25.326 (Cap. I.6) para sostener la trazabilidad ante una eventual auditoría; no bloquea la operación diaria de reserva. | G21: Dada la anonimización de los datos de una clienta ejecutada por la propietaria, cuando se consulta el registro de auditoría, aparece una entrada con fecha, hora, usuario que la ejecutó y clienta afectada, verificable en dicho registro. | H21: H-16 | I21: Validado | J21: 4 | K21: No | L21: =IF($A21="","",IF(COUNTBLANK($B21:$C21)+COUNTBLANK($E21:$H21)>0,"Faltan campos",IF(AND($C21="No funcional",$D21=""),"Falta categoría",IF($K21="","Falta definir si integra el MVP","Fila completa")))) -> Fila completa
A22: RF-13 | B22: La clienta puede reprogramar un turno propio pendiente o confirmado a otro horario libre de la misma profesional; el sistema revalida la franja y la superposición, rechaza reprogramar un turno de combo y, si reprograma el personal, avisa a la clienta por mail y en pantalla hasta que lo confirma. | C22: Funcional | E22: Should | F22: Evita que la clienta cancele y vuelva a reservar, pero el objetivo central de eliminar superposiciones ya lo cubre RF-01. | G22: Dado un turno confirmado de una clienta con la profesional X el lunes a las 10:00, cuando la clienta lo reprograma al lunes a las 11:00 y X no tiene otro turno activo a esa hora, el turno pasa a las 11:00; si X ya tiene un turno activo a las 11:00, el sistema responde 409 y el turno queda a las 10:00; si el turno es parte de un combo, el sistema lo rechaza (COMBO_NOT_RESCHEDULABLE). Verificable con appointments.cancel-reschedule. | H22: EXTRA: sin hallazgo registrado. Función construida durante el desarrollo. | I22: Pendiente | J22: Extra | K22: No | L22: =IF($A22="","",IF(COUNTBLANK($B22:$C22)+COUNTBLANK($E22:$H22)>0,"Faltan campos",IF(AND($C22="No funcional",$D22=""),"Falta categoría",IF($K22="","Falta definir si integra el MVP","Fila completa")))) -> Fila completa
A23: RF-14 | B23: El sistema cancela y libera el horario de un turno cuya seña no se pagó dentro del plazo de 20 minutos, salvo que la seña se coordine por WhatsApp; si en un combo queda impaga la pata con seña, cancela el grupo entero. | C23: Funcional | E23: Should | F23: Evita que una reserva sin pago bloquee la agenda de la profesional; completa a RF-02 y RF-03, que dejan el turno a la espera de la seña. | G23: Dado un turno con seña por Mercado Pago que sigue sin pagar al vencer el plazo, cuando corre el job de liberación, el turno pasa a cancelado y el horario queda libre para otra reserva; un turno con seña coordinada por WhatsApp no se libera; en un combo con la pata con seña impaga se cancelan todas las patas. Verificable con jobs.release-unpaid. | H23: EXTRA: sin hallazgo registrado. Función construida durante el desarrollo. | I23: Pendiente | J23: Extra | K23: No | L23: =IF($A23="","",IF(COUNTBLANK($B23:$C23)+COUNTBLANK($E23:$H23)>0,"Faltan campos",IF(AND($C23="No funcional",$D23=""),"Falta categoría",IF($K23="","Falta definir si integra el MVP","Fila completa")))) -> Fila completa
A24: RF-15 | B24: El administrador y la profesional pueden crear un turno manual para una clienta existente o nueva (por ejemplo, la que llega sin reserva previa); el turno nace confirmado, sin seña, respeta el índice de no superposición y no se valida contra las franjas de la profesional. | C24: Funcional | E24: Could | F24: Cubre la atención sin reserva web; no es necesaria para el flujo de reserva por la clienta. | G24: Dado un horario sin turno activo de la profesional X pero fuera de sus franjas, cuando el administrador crea un turno manual a esa hora, el turno se crea confirmado y sin seña; si X ya tiene un turno activo a esa hora de inicio, el sistema responde 409. Verificable con auth.minor-fixes (turno manual con clienta nueva) y la prueba «el turno manual del admin no se valida contra la franja». | H24: EXTRA: sin hallazgo registrado. Función construida durante el desarrollo. | I24: Pendiente | J24: Extra | K24: No | L24: =IF($A24="","",IF(COUNTBLANK($B24:$C24)+COUNTBLANK($E24:$H24)>0,"Faltan campos",IF(AND($C24="No funcional",$D24=""),"Falta categoría",IF($K24="","Falta definir si integra el MVP","Fila completa")))) -> Fila completa
A25: RF-16 | B25: El administrador registra el cobro del saldo del turno en el local (efectivo, transferencia, tarjeta u otro medio) y el sistema marca el turno como pagado cuando la seña más el saldo cubren el precio; no se admite sobre turnos cancelados. | C25: Funcional | E25: Could | F25: Completa el ciclo de cobro del turno; el cobro de la seña (RF-03) ya cubre el objetivo del proyecto. | G25: Dado un turno de $10.000 con seña de $5.000 pagada, cuando el administrador registra un saldo de $5.000 en efectivo, el turno pasa a estado de pago «pagado»; con un saldo de $2.000 no pasa; sobre un turno cancelado el sistema rechaza el cobro. Verificable con appointments.balance-payment. | H25: EXTRA: sin hallazgo registrado. Función construida durante el desarrollo. | I25: Pendiente | J25: Extra | K25: No | L25: =IF($A25="","",IF(COUNTBLANK($B25:$C25)+COUNTBLANK($E25:$H25)>0,"Faltan campos",IF(AND($C25="No funcional",$D25=""),"Falta categoría",IF($K25="","Falta definir si integra el MVP","Fila completa")))) -> Fila completa
A26: RF-17 | B26: El sistema permite ofrecer servicios especiales de un solo día, con horarios puntuales por profesional, zonas y paquetes; el precio y la duración los calcula el servidor a partir de lo elegido y un horario ya tomado se rechaza. | C26: Funcional | E26: Could | F26: Atiende jornadas puntuales del estudio; no forma parte del flujo de reserva de servicios comunes. | G26: Dado un servicio especial con un horario ya reservado, cuando otra clienta intenta reservar ese horario, el sistema responde 409 SLOT_TAKEN; el precio del turno es el calculado por el servidor desde las zonas y paquetes elegidos, no el que envía el navegador. Verificable revisando createSpecialForClient (sin prueba automatizada). | H26: EXTRA: sin hallazgo registrado. Función construida durante el desarrollo. | I26: Pendiente | J26: Extra | K26: No | L26: =IF($A26="","",IF(COUNTBLANK($B26:$C26)+COUNTBLANK($E26:$H26)>0,"Faltan campos",IF(AND($C26="No funcional",$D26=""),"Falta categoría",IF($K26="","Falta definir si integra el MVP","Fila completa")))) -> Fila completa
A27: RF-18 | B27: El administrador puede bloquear a una clienta; una clienta bloqueada no puede reservar turnos ni comprar productos. | C27: Funcional | E27: Could | F27: Herramienta de gestión para casos puntuales; no afecta al flujo normal de reserva. | G27: Dada una clienta bloqueada, cuando intenta reservar un turno o comprar un producto, el sistema responde 403 CLIENT_BLOCKED. Verificable con la prueba «rechaza reservar si la clienta está bloqueada»; la compra y el endpoint de bloqueo no tienen prueba. | H27: EXTRA: sin hallazgo registrado. Función construida durante el desarrollo. | I27: Pendiente | J27: Extra | K27: No | L27: =IF($A27="","",IF(COUNTBLANK($B27:$C27)+COUNTBLANK($E27:$H27)>0,"Faltan campos",IF(AND($C27="No funcional",$D27=""),"Falta categoría",IF($K27="","Falta definir si integra el MVP","Fila completa")))) -> Fila completa
A28: RF-19 | B28: El sistema ofrece una tienda de productos: catálogo público, carrito y pedido con retiro o envío, con pago por Mercado Pago o coordinado por WhatsApp; el stock se descuenta recién cuando el pago se aprueba con el monto correcto y el administrador gestiona productos y estados de los pedidos. | C28: Funcional | E28: Could | F28: Amplía el negocio más allá de los turnos; no integra el MVP ni el objetivo central de eliminar superposiciones. | G28: Dado un producto activo con stock 5 y un pedido de 2 unidades pagado por Mercado Pago con el monto correcto, cuando el pago se aprueba, el stock baja a 3 y el pedido queda pagado; con un monto menor o en otra moneda el pago no se registra y queda un aviso de error en la actividad; un pedido por más unidades que el stock se rechaza (INSUFFICIENT_STOCK). Verificable con payments.webhook-amount, payments.webhook-idempotency y whatsapp-payment (pedido). | H28: EXTRA: sin hallazgo. Función agregada por la autora (confirmado por ella el 30/10/2026); descrita en el Cap. I.5. | I28: Pendiente | J28: Extra | K28: No | L28: =IF($A28="","",IF(COUNTBLANK($B28:$C28)+COUNTBLANK($E28:$H28)>0,"Faltan campos",IF(AND($C28="No funcional",$D28=""),"Falta categoría",IF($K28="","Falta definir si integra el MVP","Fila completa")))) -> Fila completa
A29: RF-20 | B29: El administrador crea promociones de servicio o de producto (descuento, combo o «llevás X, pagás Y») con ventana de vigencia; el servidor recalcula el precio al reservar o comprar y se avisa a las clientas al activarlas. | C29: Funcional | E29: Could | F29: Apoya la venta de la tienda y de los servicios; no es necesaria para reservar. | G29: Dada una promoción vigente de $4.000 sobre un servicio de $5.000, cuando la clienta reserva ese servicio, el turno se crea a $4.000 aunque el navegador envíe otro precio; con la promoción vencida se cobra $5.000. Verificable con appointments.booking › promociones (4 casos); el alta y la edición de promociones no tienen prueba. | H29: EXTRA: sin hallazgo. Función agregada por la autora (confirmado por ella el 30/10/2026); descrita en el Cap. I.5. | I29: Pendiente | J29: Extra | K29: No | L29: =IF($A29="","",IF(COUNTBLANK($B29:$C29)+COUNTBLANK($E29:$H29)>0,"Faltan campos",IF(AND($C29="No funcional",$D29=""),"Falta categoría",IF($K29="","Falta definir si integra el MVP","Fila completa")))) -> Fila completa
A30: RF-21 | B30: El administrador registra entradas y salidas de stock de un producto; el sistema ajusta el stock en una transacción y rechaza dejarlo negativo. Los pedidos pagados descuentan stock directamente, sin crear un movimiento. | C30: Funcional | E30: Could | F30: Complementa la tienda; el administrador puede operar sin él cargando el stock en cada producto. | G30: Dado un producto con stock 3, cuando el administrador registra una salida de 5, el sistema responde INSUFFICIENT_STOCK y el stock queda en 3; una entrada de 10 lo lleva a 13. Verificable con una llamada a POST /store/movements (sin prueba automatizada). | H30: EXTRA: sin hallazgo. Función agregada por la autora (confirmado por ella el 30/10/2026); descrita en el Cap. I.5. | I30: Pendiente | J30: Extra | K30: No | L30: =IF($A30="","",IF(COUNTBLANK($B30:$C30)+COUNTBLANK($E30:$H30)>0,"Faltan campos",IF(AND($C30="No funcional",$D30=""),"Falta categoría",IF($K30="","Falta definir si integra el MVP","Fila completa")))) -> Fila completa
A31: RF-22 | B31: El administrador configura campañas automáticas (cumpleaños y hito de turno número N) y el sistema, una vez por día, envía por mail el descuento informado y registra el envío para no repetirlo; el descuento solo se informa, no se aplica solo en la reserva. | C31: Funcional | E31: Could | F31: Fidelización de clientas; no es parte del flujo de reserva. | G31: Dada una campaña de cumpleaños activa y una clienta que cumple años hoy (fecha de Argentina), cuando corre el job diario, la clienta recibe un mail y queda un registro único por año; si el job vuelve a correr el mismo día no se envía otro. Verificable con timezone-art › jobs diarios (3 casos de cumpleaños); el hito de turno N y la no repetición no tienen prueba. | H31: EXTRA: sin hallazgo. Función construida por la autora durante el desarrollo (commits 0be5ad5, 208457f y 1c90c9b, septiembre de 2026). | I31: Pendiente | J31: Extra | K31: No | L31: =IF($A31="","",IF(COUNTBLANK($B31:$C31)+COUNTBLANK($E31:$H31)>0,"Faltan campos",IF(AND($C31="No funcional",$D31=""),"Falta categoría",IF($K31="","Falta definir si integra el MVP","Fila completa")))) -> Fila completa
A32: RF-23 | B32: El administrador publica en el home un evento especial (servicio, profesional y fecha) que se oculta solo cuando pasa la fecha; la clienta lo reserva por el flujo normal. | C32: Funcional | E32: Could | F32: Da visibilidad a jornadas puntuales; no cambia las reglas de reserva. | G32: Dado un evento activo con fecha de hoy, cuando son las 22:30 hora de Argentina, el evento sigue publicado; al día siguiente deja de mostrarse. Verificable con timezone-art › «un evento especial de hoy sigue publicado a las 22:30»; el alta y la edición no tienen prueba. | H32: EXTRA: sin hallazgo. Función construida por la autora durante el desarrollo (commits 0be5ad5, 208457f y 1c90c9b, septiembre de 2026). | I32: Pendiente | J32: Extra | K32: No | L32: =IF($A32="","",IF(COUNTBLANK($B32:$C32)+COUNTBLANK($E32:$H32)>0,"Faltan campos",IF(AND($C32="No funcional",$D32=""),"Falta categoría",IF($K32="","Falta definir si integra el MVP","Fila completa")))) -> Fila completa
A33: RF-24 | B33: El sistema avisa a profesionales y clientas dentro de la aplicación y por mail de los hechos que les corresponden (turno nuevo, cancelado o reprogramado, servicio, producto o promoción nuevos); la profesional recibe el aviso de un turno nuevo recién cuando la seña está paga. No se envía ninguna notificación por WhatsApp. | C33: Funcional | E33: Should | F33: Reemplaza el aviso manual por WhatsApp que hoy hace el estudio y sostiene la coordinación de la agenda; no es indispensable para reservar. | G33: Dado un turno con seña por Mercado Pago, cuando el pago se aprueba, la profesional recibe un aviso «turno nuevo» y un mail, y no antes; en un combo recibe un solo aviso por grupo. Verificable con notifications.investigation (3 casos) y mail.provider.test; la lectura de las bandejas no tiene prueba. | H33: EXTRA: sin hallazgo registrado. Función construida durante el desarrollo. | I33: Pendiente | J33: Extra | K33: No | L33: =IF($A33="","",IF(COUNTBLANK($B33:$C33)+COUNTBLANK($E33:$H33)>0,"Faltan campos",IF(AND($C33="No funcional",$D33=""),"Falta categoría",IF($K33="","Falta definir si integra el MVP","Fila completa")))) -> Fila completa
... A43: RF-34 | B43: El administrador ve un panel con indicadores del negocio calculados por el sistema y cada profesional ve su panel y sus estadísticas. | C43: Funcional | E43: Could | F43: Da información de gestión a la propietaria; no es parte del flujo de reserva. | G43: Dado un período con turnos finalizados, cuando el administrador abre el panel, los indicadores de turnos coinciden con el listado de turnos del mismo período. Verificable comparando el panel con GET /admin/appointments (sin prueba automatizada). | H43: EXTRA: sin hallazgo registrado. Función construida durante el desarrollo. | I43: Pendiente | J43: Extra | K43: No | L43: =IF($A43="","",IF(COUNTBLANK($B43:$C43)+COUNTBLANK($E43:$H43)>0,"Faltan campos",IF(AND($C43="No funcional",$D43=""),"Falta categoría",IF($K43="","Falta definir si integra el MVP","Fila completa")))) -> Fila completa
A44: RNF-06 | B44: El sistema no envía datos personales, de contacto ni de salud al servicio de monitoreo de errores (Sentry): borra cookies, cuerpo, query string, cabeceras sensibles, correo e IP del usuario, los correos dentro de los mensajes, el texto de las consultas de Prisma, los breadcrumbs, los campos extra, los contextos ajenos al SDK y las variables locales de los stack frames. Quedan fuera del alcance las trazas de rendimiento y los console.error o throw propios con datos clínicos en texto libre. | C44: No funcional | D44: Seguridad | E44: Should | F44: Evita que una alergia llegue a un tercero a través de un mensaje de error, protegiendo el dato que RF-07 y RNF-03 resguardan; no bloquea la operación diaria. | G44: Dado un error de Prisma cuya consulta contiene allergies: «penicilina y látex», cuando Sentry lo recibe, el evento enviado no contiene ese texto ni ningún correo electrónico. Verificable con sentry.scrub.test.ts. | H44: H-14. Base legal: Ley N.º 25.326 (protección del dato de alergias). | I44: Pendiente | J44: Extra | K44: No | L44: =IF($A44="","",IF(COUNTBLANK($B44:$C44)+COUNTBLANK($E44:$H44)>0,"Faltan campos",IF(AND($C44="No funcional",$D44=""),"Falta categoría",IF($K44="","Falta definir si integra el MVP","Fila completa")))) -> Fila completa
A45: RNF-07 | B45: El sistema autentica con cookies httpOnly (el token no queda accesible a JavaScript), renueva las sesiones con rotación, admite hasta 10 sesiones por usuaria, limita los intentos de ingreso, rechaza pedidos de origen no confiable (CSRF) y cierra todas las sesiones de una usuaria al desactivarla o anonimizarla. | C45: No funcional | D45: Seguridad | E45: Should | F45: Condición transversal de todos los requisitos con datos personales; no integra el MVP original, que no definió la autenticación como requisito propio. | G45: Dado un navegador con sesión activa, cuando una página ejecuta JavaScript que lee las cookies, no encuentra el token de acceso; una usuaria desactivada no puede renovar ninguna sesión; una profesional que pide una ruta de administración es rechazada. Verificable con auth.security, auth.sessions, auth.test y hardening (ADR-003). | H45: EXTRA: sin hallazgo. Base legal: Ley N.º 25.326, art. 9 (seguridad de los datos). | I45: Pendiente | J45: Extra | K45: No | L45: =IF($A45="","",IF(COUNTBLANK($B45:$C45)+COUNTBLANK($E45:$H45)>0,"Faltan campos",IF(AND($C45="No funcional",$D45=""),"Falta categoría",IF($K45="","Falta definir si integra el MVP","Fila completa")))) -> Fila completa
A46: RNF-08 | B46: Toda decisión que depende de la hora (tolerancia de 20 minutos, corte de 12 horas, jobs diarios, vigencia de eventos y promociones, «hoy») se calcula en la hora de Argentina (America/Argentina/Buenos_Aires) y no en la del servidor. | C46: No funcional | D46: Fiabilidad | E46: Should | F46: Sin esto RF-04 y RF-05 fallarían según dónde corra el servidor; no integra el MVP original. | G46: Dado un turno a las 18:00, cuando faltan 12 horas y media reales, la cancelación devuelve la seña; con menos de 12 horas reales no la devuelve; un evento especial de hoy sigue publicado a las 22:30. Verificable con timezone-art. | H46: H-09, H-10 (plazos de 12 horas y de 20 minutos). | I46: Pendiente | J46: Extra | K46: No | L46: =IF($A46="","",IF(COUNTBLANK($B46:$C46)+COUNTBLANK($E46:$H46)>0,"Faltan campos",IF(AND($C46="No funcional",$D46=""),"Falta categoría",IF($K46="","Falta definir si integra el MVP","Fila completa")))) -> Fila completa
A47: RNF-09 | B47: El sistema acepta los avisos de Mercado Pago solo con firma válida (HMAC-SHA256), los procesa una sola vez aunque lleguen repetidos y solo registra el pago si el monto y la moneda son los esperados; un pago con monto menor o en otra moneda no se registra y deja un aviso de error. | C47: No funcional | D47: Seguridad | E47: Should | F47: Protege el cobro de la seña (RF-03) frente a avisos falsos, duplicados o por un monto distinto; no integra el MVP original. | G47: Dado un pago aprobado por un monto menor al de la seña, cuando llega el aviso, el turno sigue sin seña pagada y aparece un aviso de nivel error en la actividad; dos avisos simultáneos del mismo pago generan una sola notificación. Verificable con payments.webhook-amount y payments.webhook-idempotency; la verificación de la firma no tiene prueba. | H47: H-08. Soporte técnico de RF-03 y RNF-04. | I47: Pendiente | J47: Extra | K47: No | L47: =IF($A47="","",IF(COUNTBLANK($B47:$C47)+COUNTBLANK($E47:$H47)>0,"Faltan campos",IF(AND($C47="No funcional",$D47=""),"Falta categoría",IF($K47="","Falta definir si integra el MVP","Fila completa")))) -> Fila completa
A48: RNF-10 | B48: El código se verifica con pruebas automatizadas y chequeo de tipos que corren en cada propuesta de cambio mediante el canal de integración continua. | C48: No funcional | D48: Mantenibilidad | E48: Should | F48: Sostiene todos los requisitos ante cambios futuros; es condición de cómputo de la entrega (ejecutabilidad del repositorio). | G48: Dado el repositorio al 30/10/2026, cuando se ejecuta npm test en el backend, pasan 32 archivos y 310 tests y en el frontend 80 tests; el canal de GitHub Actions corre en cada cambio. Verificable en la última corrida del canal. | H48: EXTRA: sin hallazgo. Condición de cómputo de la entrega (consigna AE2 y AE4). | I48: Pendiente | J48: Extra | K48: No | L48: =IF($A48="","",IF(COUNTBLANK($B48:$C48)+COUNTBLANK($E48:$H48)>0,"Faltan campos",IF(AND($C48="No funcional",$D48=""),"Falta categoría",IF($K48="","Falta definir si integra el MVP","Fila completa")))) -> Fila completa
L49: =IF($A49="","",IF(COUNTBLANK($B49:$C49)+COUNTBLANK($E49:$H49)>0,"Faltan campos",IF(AND($C49="No funcional",$D49=""),"Falta categoría",IF($K49="","Falta definir si integra el MVP","Fila completa"))))
L50: =IF($A50="","",IF(COUNTBLANK($B50:$C50)+COUNTBLANK($E50:$H50)>0,"Faltan campos",IF(AND($C50="No funcional",$D50=""),"Falta categoría",IF($K50="","Falta definir si integra el MVP","Fila completa"))))
...

Sheet Trazabilidad
A1: Matriz de trazabilidad · hallazgo de la AE1 → requisito
A2: Se verifica en doble vía. Todo requisito llega a un hallazgo; todo hallazgo llega a un requisito o a una justificación expresa de por qué no derivó ninguno. El silencio no es una decisión.
A4: Código (H-01, H-02…) | B4: Hallazgo de la AE1 (dato y valor) | C4: Fuente (apartado del Cap. II o acta) | D4: Requisito(s) derivado(s) | E4: Si no deriva: justificación | F4: Control de la doble vía | G4: Componente(s) que lo satisfacen (detalle en la hoja «Código y pruebas») | H4: Prueba(s) que lo verifican
A5: H-01 | B5: Registro de chat de WhatsApp del 24/11/2025: superposición de un turno a las 16:00 h pese a estar confirmado dos semanas antes en el registro físico; el horario seguía figurando disponible por falta de sincronización digital. | C5: Cap. I.1, evidencia fechada | D5: RF-01 | F5: =IF($A5="","",IF(AND($D5="",$E5=""),"Hallazgo sin destino",IF($D5="","Sin requisito, justificado","Deriva requisito"))) -> Deriva requisito | G5: RF-01: Índice único parcial por profesional, fecha y hora de inicio; createForClient; assertWithinAvailability | H5: RF-01: appointments.booking, appointments.out-of-hours, appointments.cancel-reschedule
A6: H-02 | B6: Línea de base cuantificada: 10 turnos superpuestos por mes sobre 120 turnos individuales de Loren (8,33% de error), medida entre noviembre de 2025 y julio de 2026 cruzando la agenda de papel con los chats de WhatsApp. | C6: Cap. I.3, línea de base | D6: RF-01 | F6: =IF($A6="","",IF(AND($D6="",$E6=""),"Hallazgo sin destino",IF($D6="","Sin requisito, justificado","Deriva requisito"))) -> Deriva requisito | G6: RF-01: Índice único parcial por profesional, fecha y hora de inicio; createForClient; assertWithinAvailability | H6: RF-01: appointments.booking, appointments.out-of-hours, appointments.cancel-reschedule
A7: H-03 | B7: Costo de oportunidad mensual estimado entre $150.000 y $540.000 ARS por clientas que desisten de reservar o reagendar tras un conflicto de agenda. | C7: Cap. I.3, consecuencia acreditada | E7: No deriva un requisito propio: es el impacto económico que sostiene la prioridad «Must» de RF-01, RF-03 y RF-04, no una funcionalidad nueva del sistema. | F7: =IF($A7="","",IF(AND($D7="",$E7=""),"Hallazgo sin destino",IF($D7="","Sin requisito, justificado","Deriva requisito"))) -> Sin requisito, justificado
A8: H-04 | B8: El estudio opera sin ningún sistema de información formal: no existe una base de datos centralizada de clientas, turnos, señas ni profesionales. | C8: Cap. I.3, diagnóstico del SI actual | D8: RF-02, RF-11 | F8: =IF($A8="","",IF(AND($D8="",$E8=""),"Hallazgo sin destino",IF($D8="","Sin requisito, justificado","Deriva requisito"))) -> Deriva requisito | G8: RF-02: registerDto; auth.service › register; createForClient; displayStatusOf | RF-11: service.controller; service.model | H8: RF-02: auth.test, appointments.booking | RF-11: Sin prueba del alta ni del listado
A9: H-05 | B9: El 93,57% (131 de 140) de los establecimientos de estética relevados en Posadas opera sin ningún sistema digital; solo 9 (6,43%) cuentan con web o plataforma propia. | C9: Cap. II.1 y II.5, relevamiento propio en Google Maps, agosto de 2026 | E9: No deriva un requisito: es evidencia de contexto de mercado (PESTEL/FODA) que descarta la presión competitiva como desencadenante, no una funcionalidad del sistema. | F9: =IF($A9="","",IF(AND($D9="",$E9=""),"Hallazgo sin destino",IF($D9="","Sin requisito, justificado","Deriva requisito"))) -> Sin requisito, justificado
A10: H-06 | B10: El estudio recibe entre 20 y 30 mensajes de WhatsApp diarios, en su mayoría consultas repetitivas sobre disponibilidad, precios y señas. | C10: Cap. II.3 y II.5; entrevista a Loren, 26/08/2026 | D10: RNF-01 | F10: =IF($A10="","",IF(AND($D10="",$E10=""),"Hallazgo sin destino",IF($D10="","Sin requisito, justificado","Deriva requisito"))) -> Deriva requisito | G10: RNF-01: Sin componente específico | H10: RNF-01: Sin prueba
A11: H-07 | B11: La conciliación manual de un turno insume entre 10 y 15 minutos por consulta, tomada como línea de base del Objetivo específico N.º 4. | C11: Cap. II.3 | D11: RNF-01 | F11: =IF($A11="","",IF(AND($D11="",$E11=""),"Hallazgo sin destino",IF($D11="","Sin requisito, justificado","Deriva requisito"))) -> Deriva requisito | G11: RNF-01: Sin componente específico | H11: RNF-01: Sin prueba
A12: H-08 | B12: Seña fija de $5.000 ARS para turnos individuales, o del 50% del valor para talleres, cobrada manualmente por transferencia bancaria sin trazabilidad automatizada. | C12: Cap. I.3 y II.3; Anexo I | D12: RF-03, RNF-04 | F12: =IF($A12="","",IF(AND($D12="",$E12=""),"Hallazgo sin destino",IF($D12="","Sin requisito, justificado","Deriva requisito"))) -> Deriva requisito | G12: RF-03: computeDeposit; createPaymentPreference; applyPaymentResult; webhook de Mercado Pago | RNF-04: schema.prisma (solo mpPaymentId) | H12: RF-03: whatsapp-payment, payments.webhook-amount, payments.webhook-idempotency | RNF-04: schema.no-card-data
A13: H-09 | B13: Política de cancelación relevada: devolución total con aviso de 12 horas o más; retención del 100% de la seña con aviso menor a 12 horas o no-show. | C13: Cap. I.6 y II.3 | D13: RF-04 | F13: =IF($A13="","",IF(AND($D13="",$E13=""),"Hallazgo sin destino",IF($D13="","Sin requisito, justificado","Deriva requisito"))) -> Deriva requisito | G13: RF-04: cancelWithGroup; cancelForClient; PaymentSettings.cancellationHours | H13: RF-04: appointments.cancel-reschedule, timezone-art
A14: H-10 | B14: Tolerancia de llegada de 20 minutos desde el horario pactado; superado ese margen, el turno se cancela para no demorar la agenda subsiguiente. | C14: Cap. I.6 y II.3 | D14: RF-05 | F14: =IF($A14="","",IF(AND($D14="",$E14=""),"Hallazgo sin destino",IF($D14="","Sin requisito, justificado","Deriva requisito"))) -> Deriva requisito | G14: RF-05: runAutoNoShowJob; scheduler; registerArrival | H14: RF-05: appointments.arrival-noshow, timezone-art
A15: H-11 | B15: Hoy Loren asigna a la profesional por antigüedad y disponibilidad, sin asignación automática (entrevista a Loren); el sistema debe asignar automáticamente, cuando la clienta no elige una en particular, a la profesional libre con menos turnos en la semana y, a igual carga, a la de mayor antigüedad. | C15: Cap. I.6, módulos funcionales; Anexo I, entrevista a Loren | D15: RF-06 | F15: =IF($A15="","",IF(AND($D15="",$E15=""),"Hallazgo sin destino",IF($D15="","Sin requisito, justificado","Deriva requisito"))) -> Deriva requisito | G15: RF-06: resolveProfessionalId; previewAnyProfessional; weekRangeOf | H15: RF-06: appointments.booking
A16: H-12 | B16: Distintos tipos de servicio requieren datos específicos (uñas: cantidad y reconstrucción; cabello: largo y extensiones; rostro: tipo de piel), y permiten adjuntar imágenes o textos de referencia. | C16: Cap. I.6 | E16: No deriva un requisito propio de este catálogo: son variantes de captura de datos por categoría de servicio que se resuelven en el diseño del formulario de reserva, no una restricción de negocio autónoma. | F16: =IF($A16="","",IF(AND($D16="",$E16=""),"Hallazgo sin destino",IF($D16="","Sin requisito, justificado","Deriva requisito"))) -> Sin requisito, justificado
A17: H-13 | B17: La información de alergias y tipo de piel hoy se releva de forma verbal e informal, sin ningún registro sistemático. | C17: Cap. II.6, conclusiones del relevamiento | D17: RF-07, RNF-03 | F17: =IF($A17="","",IF(AND($D17="",$E17=""),"Hallazgo sin destino",IF($D17="","Sin requisito, justificado","Deriva requisito"))) -> Deriva requisito | G17: RF-07: detailsSchema; updateDetailsForClient; assertAllergiesUnchanged | RNF-03: toProfessionalView; listClientsForProfessional; mapAdminClient | H17: RF-07: allergies.consent-visibility | RNF-03: allergies.consent-visibility
A18: H-14 | B18: Exigencia de consentimiento diferenciado para guardar datos de alergias o piel sensible, conforme a la Ley N.º 25.326. | C18: Cap. I.6 y I.7 | D18: RF-07, RNF-03 | F18: =IF($A18="","",IF(AND($D18="",$E18=""),"Hallazgo sin destino",IF($D18="","Sin requisito, justificado","Deriva requisito"))) -> Deriva requisito | G18: RF-07: detailsSchema; updateDetailsForClient; assertAllergiesUnchanged | RNF-03: toProfessionalView; listClientsForProfessional; mapAdminClient | H18: RF-07: allergies.consent-visibility | RNF-03: allergies.consent-visibility
A19: H-15 | B19: Exigencia de exponer la política de privacidad antes de registrar datos personales, con registro de fecha, hora y versión aceptada. | C19: Cap. I.6, Ley N.º 25.326 Art. 25 | D19: RF-08 | F19: =IF($A19="","",IF(AND($D19="",$E19=""),"Hallazgo sin destino",IF($D19="","Sin requisito, justificado","Deriva requisito"))) -> Deriva requisito | G19: RF-08: register; PRIVACY_POLICY_VERSION; RegisterForm.tsx | H19: RF-08: terms-version, auth.test
A20: H-16 | B20: Exigencia de que la propietaria pueda eliminar o anonimizar datos personales a pedido de la titular, con constancia de auditoría, preservando solo los registros contables o fiscales exigidos. | C20: Cap. I.6 y I.7, Ley N.º 25.326 Art. 25 | D20: RF-09, RNF-05 | F20: =IF($A20="","",IF(AND($D20="",$E20=""),"Hallazgo sin destino",IF($D20="","Sin requisito, justificado","Deriva requisito"))) -> Deriva requisito | G20: RF-09: anonymizeClient; ClientDetail.tsx | RNF-05: activity.service › log; logStatusChange; anonymizeClient | H20: RF-09: admin.clients | RNF-05: appointments.status-log, admin.clients
A21: H-17 | B21: Existencia de servicios simultáneos con dos profesionales distintas, hoy coordinados de forma manual y verbal entre ellas. | C21: Anexo I, entrevista a Loren | D21: RF-10 | F21: =IF($A21="","",IF(AND($D21="",$E21=""),"Hallazgo sin destino",IF($D21="","Sin requisito, justificado","Deriva requisito"))) -> Deriva requisito | G21: RF-10: createComboForClient; comboGroupId | H21: RF-10: appointments.combo-deposit, appointments.combo
A22: H-18 | B22: Preferencia relevada de las clientas por un flujo web liviano desde el navegador, sin descarga de aplicaciones nativas. | C22: Cap. II.6, conclusiones del relevamiento | D22: RNF-02 | F22: =IF($A22="","",IF(AND($D22="",$E22=""),"Hallazgo sin destino",IF($D22="","Sin requisito, justificado","Deriva requisito"))) -> Deriva requisito | G22: RNF-02: Frontend web (sin app nativa) | H22: RNF-02: Sin prueba
A23: H-19 | B23: Catálogo de servicios organizado en cuatro categorías (uñas, cabello, cuerpo, rostro), con precios y duraciones diferenciados por técnica, hoy no sistematizado en ningún registro único. | C23: Cap. II.3, síntesis del catálogo relevado | D23: RF-11 | F23: =IF($A23="","",IF(AND($D23="",$E23=""),"Hallazgo sin destino",IF($D23="","Sin requisito, justificado","Deriva requisito"))) -> Deriva requisito | G23: RF-11: service.controller; service.model | H23: RF-11: Sin prueba del alta ni del listado
A24: H-20 | B24: El estudio atiende de forma autónoma a partir de los 13 años; para menores de 13, la reserva y gestión del turno la realiza exclusivamente la madre, padre o tutor, sin registrar datos identificatorios de la menor. | C24: Cap. I.7, atención de menores y registro de acompañantes | D24: RF-12 | F24: =IF($A24="","",IF(AND($D24="",$E24=""),"Hallazgo sin destino",IF($D24="","Sin requisito, justificado","Deriva requisito"))) -> Deriva requisito | G24: RF-12: COMPANION_RELATIONS; CHECK en la base | H24: RF-12: appointments.companion
A25: H-21 | B25: Ocho plataformas genéricas de reserva evaluadas y descartadas (ReservaSimple, Agenda+, AgendaPro, WeiBook, MiAgendaProfesional, Tiska, Turnau, Booksy) por costos dolarizados o suscripciones fijas inviables, y por no adaptarse al esquema local de alquiler más comisión. | C25: Cap. I.4 | E25: No deriva un requisito: es la evidencia que sostiene la decisión de construir un sistema a medida en vez de adoptar una plataforma genérica, no una funcionalidad concreta de Nexa. | F25: =IF($A25="","",IF(AND($D25="",$E25=""),"Hallazgo sin destino",IF($D25="","Sin requisito, justificado","Deriva requisito"))) -> Sin requisito, justificado
F26: =IF($A26="","",IF(AND($D26="",$E26=""),"Hallazgo sin destino",IF($D26="","Sin requisito, justificado","Deriva requisito")))
F27: =IF($A27="","",IF(AND($D27="",$E27=""),"Hallazgo sin destino",IF($D27="","Sin requisito, justificado","Deriva requisito")))
F28: =IF($A28="","",IF(AND($D28="",$E28=""),"Hallazgo sin destino",IF($D28="","Sin requisito, justificado","Deriva requisito")))
F29: =IF($A29="","",IF(AND($D29="",$E29=""),"Hallazgo sin destino",IF($D29="","Sin requisito, justificado","Deriva requisito")))
F30: =IF($A30="","",IF(AND($D30="",$E30=""),"Hallazgo sin destino",IF($D30="","Sin requisito, justificado","Deriva requisito")))
F31: =IF($A31="","",IF(AND($D31="",$E31=""),"Hallazgo sin destino",IF($D31="","Sin requisito, justificado","Deriva requisito")))
F32: =IF($A32="","",IF(AND($D32="",$E32=""),"Hallazgo sin destino",IF($D32="","Sin requisito, justificado","Deriva requisito")))
F33: =IF($A33="","",IF(AND($D33="",$E33=""),"Hallazgo sin destino",IF($D33="","Sin requisito, justificado","Deriva requisito")))
F34: =IF($A34="","",IF(AND($D34="",$E34=""),"Hallazgo sin destino",IF($D34="","Sin requisito, justificado","Deriva requisito")))
F35: =IF($A35="","",IF(AND($D35="",$E35=""),"Hallazgo sin destino",IF($D35="","Sin requisito, justificado","Deriva requisito")))
F36: =IF($A36="","",IF(AND($D36="",$E36=""),"Hallazgo sin destino",IF($D36="","Sin requisito, justificado","Deriva requisito")))
F37: =IF($A37="","",IF(AND($D37="",$E37=""),"Hallazgo sin destino",IF($D37="","Sin requisito, justificado","Deriva requisito")))
... F61: =IF($A61="","",IF(AND($D61="",$E61=""),"Hallazgo sin destino",IF($D61="","Sin requisito, justificado","Deriva requisito")))
A63: Matriz de trazabilidad · requisito → componente que lo satisface (al estado de la etiqueta v1.3, rutas de nexa-backend y nexa-frontend)
A64: Requisito | B64: Componente del backend | C64: Componente del frontend
A65: RF-01 | B65: appointments/appointment.service.ts (isSlotConflict, createForClient) e índice único parcial de la base (migración 20260826153839; recreado en 20261028160000) | C65: features/client/booking/BookingWizard.tsx y steps/DateTimeStep.tsx
...

Sheet Entidades
A1: Lista filtrada de entidades del dominio · Instrumento 28
A2: Cada candidata pasa por el filtro de las tres preguntas. Las descartadas no se borran: se reclasifican, porque los descartes de hoy son las preguntas del glosario de mañana.
A4: Candidata (sustantivo de la organización) | B4: ¿Identidad propia? | C4: ¿Datos y reglas propios? | D4: ¿Dentro del recorte? | E4: Veredicto | F4: Fuente que la acredita | G4: Relaciones principales
A5: Turno | B5: Sí | C5: Sí | D5: Sí | E5: Entidad | F5: Cap. I.6, módulos funcionales; Cap. I.3, línea de base de turnos superpuestos | G5: Un turno pertenece a una clienta y a una profesional; puede agruparse con otros turnos simultáneos de la misma reserva.
A6: Profesional | B6: Sí | C6: Sí | D6: Sí | E6: Entidad | F6: Cap. II.3, capacidad operativa (7 profesionales); Anexo I, entrevista a Loren | G6: Una profesional atiende muchos turnos; ofrece uno o varios servicios del catálogo.
A7: Clienta | B7: Sí | C7: Sí | D7: Sí | E7: Entidad | F7: Cap. I.6, captura de información en el registro; Cap. II.1, fuentes primarias | G7: Una clienta reserva muchos turnos; puede tener observaciones operativas asociadas.
A8: Servicio | B8: Sí | C8: Sí | D8: Sí | E8: Entidad | F8: Cap. II.3, síntesis del catálogo relevado (uñas, cabello, cuerpo, rostro) | G8: Un servicio pertenece a una categoría; es ofrecido por una o varias profesionales; es elegido en muchos turnos.
A9: Producto | B9: Sí | C9: Sí | D9: Sí | E9: Entidad | F9: Cap. I.5, descripción breve del sistema de información («comprar productos»); modelos Product y Order; RF-19. Función agregada por la autora (confirmado el 30/10/2026). | G9: Un producto puede incluirse en muchos pedidos de la tienda.
A10: Promoción | B10: Sí | C10: Sí | D10: Sí | E10: Entidad | F10: Cap. I.5, descripción breve del sistema de información («crear promociones»); modelo Promotion; RF-20. | G10: Una promoción se aplica sobre uno o varios servicios o productos.
A11: Categoría de servicio | B11: Parcialmente | C11: No | D11: Sí | E11: Atributo de otra entidad | F11: Cap. II.3, síntesis del catálogo relevado (cuatro categorías: uñas, cabello, cuerpo, rostro) | G11: Clasifica al Servicio; no tiene reglas de negocio propias más allá de agrupar.
A12: Seña | B12: No | C12: Sí | D12: Sí | E12: Atributo de otra entidad | F12: Cap. I.6, cobro de la seña; Cap. II.3, condiciones financieras y señas | G12: No existe sin un Turno asociado; hereda su estado del ciclo de vida del turno.
