Workbook

Sheet Instrucciones
A1: Libro de trabajo de la AE2 · Proyecto Final de Grado 2026
A2: Universidad de la Cuenca del Plata · Ingeniería en Sistemas de Información · Comisión A · Sede Posadas · Docente Titular: PosDr. Darío Ezequiel Díaz · ISI-PFG-2026C2-AE2-v02
A4: Para qué sirve este libro | B4: Reúne, en un solo archivo versionable, los instrumentos de la Unidad Dos que producen el Capítulo III y alimentan los Capítulos V y X: el catálogo de requisitos, la matriz de trazabilidad, el filtro de entidades, el registro de reglas, el glosario, el plan de iteraciones y el dimensionamiento de recursos. La hoja «Panel» controla sola el estado de completitud y avisa qué falta.
A5: Dónde se guarda | B5: En el repositorio del equipo, carpeta /03-requisitos, con la nomenclatura de la cátedra: AAAAMMDD_CatalogoRequisitos_Equipo_vN.xlsx. Se versiona cada vez que se cierra un bloque de filas, no una sola vez antes de la entrega.
A6: Qué celdas se completan | B6: Todas las celdas blancas y grises de cada hoja, a partir de la fila 5. Las filas sombreadas en ocre son ejemplos resueltos sobre el caso conductor «Santa Ana»: se leen, no se copian, y se borran antes de entregar. Las columnas de control, sombreadas en amarillo, contienen fórmulas: no se escriben.
A7: Cómo se usan las listas desplegables | B7: Las columnas de tipo, prioridad y estado admiten sólo los valores de la lista. Si un valor es rechazado, es porque la categoría no corresponde a la clasificación de la cátedra.
A8: Qué mira la corrección | B8: Que cada requisito tenga sus seis campos, que su criterio de aceptación sea un procedimiento ejecutable por un tercero, que la trazabilidad cierre en doble vía y que el conjunto de los requisitos «Must» coincida con el producto mínimo viable del apartado V.5.
A9: Orden de trabajo sugerido | B9: 1) Entidades y Reglas, en el taller. 2) Trazabilidad, con los hallazgos de la AE1 codificados H-01, H-02… 3) Catálogo, derivando requisitos de esos hallazgos. 4) Sesión de validación con el referente y actualización de los estados. 5) Iteraciones y Recursos, ya con el catálogo cerrado.
A10: Advertencia | B10: Ante divergencia entre este libro y la Consigna ISI-PFG-2026C2-AE2-v02, prevalece la consigna. Ante divergencia entre la consigna y la Resolución Rectoral UCP N.º 97/23, prevalece la Resolución.
A12: Leyenda de colores
A13: Ocre | B13: Fila de ejemplo resuelta sobre el caso «Santa Ana». Se borra antes de entregar.
A14: Amarillo | B14: Celda con fórmula de control. No se escribe.
A15: Blanco y gris | B15: Celdas que completa el equipo.

Sheet Catálogo
A1: Catálogo de requisitos · apartado III.5 del informe
A2: Una fila por requisito, con los seis campos completos. Regla de cómputo: un requisito sin criterio de aceptación comprobable no se computa, por bien redactado que esté. Antes de cerrar una fila, aplique la prueba del compañero: otro integrante debe poder decir, en diez segundos, cómo verificaría el requisito.
A4: ID | B4: Enunciado | C4: Tipo | D4: Categoría (si es no funcional) | E4: Prioridad | F4: Motivo de la prioridad | G4: Criterio de aceptación (condición, acción, resultado con valores) | H4: Trazabilidad (H-xx o acta) | I4: Estado de validación | J4: Iteración prevista | K4: ¿Integra el MVP? | L4: Control de completitud
A5: RF-01 | B5: El sistema rechaza la confirmación de la reserva de un turno cuando la profesional seleccionada ya tiene otro turno activo (no cancelado) el mismo día y a la misma hora de inicio, dentro de las franjas de atención que ella define. | C5: Funcional | E5: Must | F5: Es el «primer requisito derivado» explícito del informe (Cap. I.3) y la condición central de éxito del proyecto: reducir a 0 las superposiciones de turno. | G5: Dado un turno ya confirmado para la profesional X el día D a las H, cuando otra clienta intenta reservar a la misma profesional X, el mismo día D y la misma hora H, el sistema rechaza la reserva y no la registra en la base, verificable repitiendo la reserva y consultando la tabla de turnos. | H5: H-01, H-02 | I5: Validado | J5: 1 | K5: Sí | L5: =IF($A5="","",IF(COUNTBLANK($B5:$C5)+COUNTBLANK($E5:$H5)>0,"Faltan campos",IF(AND($C5="No funcional",$D5=""),"Falta categoría",IF($K5="","Falta definir si integra el MVP","Fila completa")))) -> Fila completa
A6: RF-02 | B6: El sistema permite a una visitante reservar un turno mediante un formulario web, dando de alta su propia cuenta con nombre, apellido y teléfono celular. | C6: Funcional | E6: Must | F6: Es el mecanismo que reemplaza la coordinación por WhatsApp y cuaderno físico, causa raíz identificada del problema (Cap. I.1, I.3). | G6: Dado un visitante sin cuenta, cuando completa el formulario con nombre, apellido y teléfono celular (los tres obligatorios y en campos separados) y elige servicio y horario, el sistema crea la cuenta y el turno queda registrado como «Pendiente de seña» hasta que la seña se pague, verificable en el listado de turnos de la clienta. | H6: H-04 | I6: Validado | J6: 1 | K6: Sí | L6: =IF($A6="","",IF(COUNTBLANK($B6:$C6)+COUNTBLANK($E6:$H6)>0,"Faltan campos",IF(AND($C6="No funcional",$D6=""),"Falta categoría",IF($K6="","Falta definir si integra el MVP","Fila completa")))) -> Fila completa
A7: RF-03 | B7: El sistema calcula la seña según el valor que la propietaria define en Configuración (un monto fijo en pesos o un porcentaje del servicio; hoy $5.000 ARS) y permite pagarla con Mercado Pago (hoy en modo prueba, con tarjeta de prueba) o coordinarla por WhatsApp; el turno queda confirmado con la seña pendiente hasta que se acredita o la propietaria la marca como pagada. | C7: Funcional | E7: Must | F7: Objetivo específico N.º 3 del proyecto (Cap. I.2): reemplaza el cobro manual de señas por transferencia que relevó H-08. El monto lo decide la propietaria, que hoy cobra $5.000. | G7: Dado un turno de precio P y una seña configurada en $5.000, cuando la clienta confirma la reserva y elige Mercado Pago, el sistema genera el cobro por el monto configurado; el turno queda confirmado con la seña «pendiente» y esta pasa a «pagada» cuando la pasarela acredita el pago. Si elige coordinar por WhatsApp, la seña queda «pendiente» hasta que la propietaria la marca como pagada. Verificable en el estado de pago del turno y en el valor de la seña de Configuración. | H7: H-08 | I7: Validado | J7: 2 | K7: Sí | L7: =IF($A7="","",IF(COUNTBLANK($B7:$C7)+COUNTBLANK($E7:$H7)>0,"Faltan campos",IF(AND($C7="No funcional",$D7=""),"Falta categoría",IF($K7="","Falta definir si integra el MVP","Fila completa")))) -> Fila completa
A8: RF-04 | B8: El sistema devuelve el 100% de la seña si la clienta cancela con 12 horas o más de anticipación al turno, y retiene el 100% si cancela con menos de 12 horas o no se presenta. | C8: Funcional | E8: Must | F8: Regla de negocio explícita relevada en la entrevista a la propietaria (R-02); condiciona la confianza de las clientas en el cobro de señas. | G8: Dado un turno con seña pagada, pactado a las 18:00 h del día D, cuando la clienta cancela a las 05:00 h del mismo día D (menos de 12 horas antes), el sistema marca la seña como retenida; cuando cancela un día antes a las 17:00 h (más de 12 horas antes), el sistema marca la seña como a devolver, verificable en el estado de pago del turno. | H8: H-09 | I8: Validado | J8: 2 | K8: Sí | L8: =IF($A8="","",IF(COUNTBLANK($B8:$C8)+COUNTBLANK($E8:$H8)>0,"Faltan campos",IF(AND($C8="No funcional",$D8=""),"Falta categoría",IF($K8="","Falta definir si integra el MVP","Fila completa")))) -> Fila completa
A9: RF-05 | B9: El sistema cancela automáticamente un turno y libera el horario para reasignar si transcurren más de 20 minutos desde la hora pactada sin que la clienta registre su llegada. | C9: Funcional | E9: Should | F9: Evita demoras en la agenda subsiguiente (Cap. I.6), pero no es indispensable para el objetivo central de eliminar superposiciones. | G9: Dado un turno pactado a las 10:00 h, cuando el reloj del sistema marca las 10:21 h sin registro de llegada de la clienta, el turno pasa a estado «cancelado por inasistencia» y el horario queda disponible para nueva reserva, verificable en el estado del turno y en la grilla de disponibilidad. | H9: H-10 | I9: Validado | J9: 3 | K9: No | L9: =IF($A9="","",IF(COUNTBLANK($B9:$C9)+COUNTBLANK($E9:$H9)>0,"Faltan campos",IF(AND($C9="No funcional",$D9=""),"Falta categoría",IF($K9="","Falta definir si integra el MVP","Fila completa")))) -> Fila completa
A10: RF-06 | B10: Cuando la clienta no indica preferencia por una profesional, el sistema asigna automáticamente el turno a la profesional disponible en ese día y hora, habilitada para el servicio, con menos turnos en la semana; a igual carga, la de mayor antigüedad. | C10: Funcional | E10: Should | F10: Mejora la distribución de la carga de trabajo (Cap. I.6), pero la clienta puede igualmente elegir profesional de forma manual, por lo que no bloquea el objetivo central. | G10: Dadas tres profesionales habilitadas para «manicura» y libres a la hora pedida, con 8, 5 y 5 turnos reservados en la semana, cuando una clienta reserva «manicura» sin elegir profesional, el sistema asigna el turno a la de mayor antigüedad entre las dos con 5 turnos, verificable en el campo de profesional asignada del turno creado. | H10: H-11 | I10: Validado | J10: 3 | K10: No | L10: =IF($A10="","",IF(COUNTBLANK($B10:$C10)+COUNTBLANK($E10:$H10)>0,"Faltan campos",IF(AND($C10="No funcional",$D10=""),"Falta categoría",IF($K10="","Falta definir si integra el MVP","Fila completa")))) -> Fila completa
A11: RF-07 | B11: El sistema solicita un consentimiento diferenciado y específico antes de guardar cualquier dato de alergias o sensibilidad de piel de la clienta, e impide su guardado si no se otorga. | C11: Funcional | E11: Must | F11: Exigencia directa de la Ley N.º 25.326 relevada en Cap. I.6 y I.7; su incumplimiento expone legalmente al proyecto. | G11: Dado el formulario de detalles de la reserva con el campo «alergias» completado, cuando la clienta no marca la casilla de consentimiento, el sistema no guarda ese valor en la base; cuando sí la marca, el valor se guarda junto con la fecha y hora del consentimiento, verificable en el registro de la reserva. | H11: H-13, H-14 | I11: Validado | J11: 2 | K11: Sí | L11: =IF($A11="","",IF(COUNTBLANK($B11:$C11)+COUNTBLANK($E11:$H11)>0,"Faltan campos",IF(AND($C11="No funcional",$D11=""),"Falta categoría",IF($K11="","Falta definir si integra el MVP","Fila completa")))) -> Fila completa
A12: RF-08 | B12: El sistema expone la política de privacidad a la clienta antes de registrar cualquier dato personal, impide continuar el flujo si la rechaza, y registra fecha, hora y versión aceptada. | C12: Funcional | E12: Must | F12: Exigencia de los Art. 21 y 25 de la Ley N.º 25.326 (Cap. I.6, I.7). | G12: Dado un nuevo registro de clienta, cuando no acepta la política de privacidad, el formulario no avanza al paso siguiente; cuando la acepta, el sistema graba fecha, hora y número de versión de la política en el registro del usuario, verificable en la base. | H12: H-15 | I12: Validado | J12: 1 | K12: Sí | L12: =IF($A12="","",IF(COUNTBLANK($B12:$C12)+COUNTBLANK($E12:$H12)>0,"Faltan campos",IF(AND($C12="No funcional",$D12=""),"Falta categoría",IF($K12="","Falta definir si integra el MVP","Fila completa")))) -> Fila completa
A13: RF-09 | B13: El sistema permite a la propietaria ejecutar la eliminación o anonimización de los datos personales de una clienta que lo solicite, preservando solo los registros exigidos por obligaciones contables o fiscales, y deja constancia de auditoría. | C13: Funcional | E13: Should | F13: Exigencia legal (Cap. I.6, Art. 25 Ley N.º 25.326), pero de volumen de uso bajo esperado en esta primera etapa; no bloquea el objetivo central del proyecto. | G13: Dada una clienta que solicita la baja de sus datos, cuando la propietaria confirma la anonimización desde el panel, el nombre y el contacto de la clienta dejan de ser recuperables en las consultas del sistema, y se genera un registro con fecha, hora y alcance de la operación en el log de auditoría, verificable en ambas consultas. | H13: H-16 | I13: Validado | J13: 4 | K13: No | L13: =IF($A13="","",IF(COUNTBLANK($B13:$C13)+COUNTBLANK($E13:$H13)>0,"Faltan campos",IF(AND($C13="No funcional",$D13=""),"Falta categoría",IF($K13="","Falta definir si integra el MVP","Fila completa")))) -> Fila completa
A14: RF-10 | B14: El sistema permite reservar, dentro de un mismo turno, dos o más servicios a cargo de profesionales distintas de forma coordinada, con una sola seña para todos los servicios y todas las profesionales, sin requerir coordinación manual entre ellas. | C14: Funcional | E14: Should | F14: Reduce una coordinación hoy manual y verbal (Anexo I), pero afecta a una porción acotada de las reservas frente al volumen total. | G14: Dada una clienta que reserva «uñas + cejas» para el mismo horario, cuando confirma la reserva, el sistema crea los turnos vinculados —uno por profesional— con el mismo horario de inicio y cobra una sola seña por el combo, verificable en el campo de agrupación de los turnos y en que la seña se registra una única vez. | H14: H-17 | I14: Validado | J14: 3 | K14: No | L14: =IF($A14="","",IF(COUNTBLANK($B14:$C14)+COUNTBLANK($E14:$H14)>0,"Faltan campos",IF(AND($C14="No funcional",$D14=""),"Falta categoría",IF($K14="","Falta definir si integra el MVP","Fila completa")))) -> Fila completa
A15: RF-11 | B15: El sistema centraliza en un catálogo único los servicios ofrecidos, organizados en las categorías uñas, cabello, cuerpo y rostro, cada uno con su precio y duración. | C15: Funcional | E15: Must | F15: Objetivo específico N.º 1 del proyecto (centralizar la información hoy dispersa); sin catálogo no hay reserva posible. | G15: Dado el panel de administración, cuando la propietaria da de alta un servicio con nombre, categoría, precio y duración, el servicio queda disponible para ser elegido por las clientas en el flujo de reserva, verificable en el listado público de servicios. | H15: H-04, H-19 | I15: Validado | J15: 1 | K15: Sí | L15: =IF($A15="","",IF(COUNTBLANK($B15:$C15)+COUNTBLANK($E15:$H15)>0,"Faltan campos",IF(AND($C15="No funcional",$D15=""),"Falta categoría",IF($K15="","Falta definir si integra el MVP","Fila completa")))) -> Fila completa
A16: RF-12 | B16: El sistema registra, en la reserva de una clienta menor de 13 años gestionada por la cuenta de su madre, padre o tutor, únicamente la condición de acompañante y su vínculo, sin ningún dato identificatorio de la menor. | C16: Funcional | E16: Must | F16: Exigencia directa del principio de minimización de datos bajo la Ley N.º 25.326 (Cap. I.7); su incumplimiento expone legalmente al proyecto frente al tratamiento de datos de menores. | G16: Dada una reserva gestionada por una cuenta adulta que marca «acompañante: sí» y elige el vínculo «hija/hijo», cuando se guarda el turno, el sistema registra solo la condición de acompañante y el vínculo de una lista cerrada (hija/hijo, pareja, familiar, amiga/o, otra), sin ningún campo de nombre, edad ni documento de la menor, verificable en el esquema de datos del turno y en el formulario resultante. | H16: H-20 | I16: Validado | J16: 2 | K16: Sí | L16: =IF($A16="","",IF(COUNTBLANK($B16:$C16)+COUNTBLANK($E16:$H16)>0,"Faltan campos",IF(AND($C16="No funcional",$D16=""),"Falta categoría",IF($K16="","Falta definir si integra el MVP","Fila completa")))) -> Fila completa
A17: RNF-01 | B17: El flujo de reserva web (selección de servicio, horario y confirmación) responde en dispositivos móviles con conexión 4G en 5 segundos o menos entre la selección del horario y la confirmación de la reserva, sin esperar la respuesta manual del estudio. | C17: No funcional | D17: Rendimiento | E17: Must | F17: Cap. II.5 (PESTEL social) exige explícitamente un «flujo ultrarrápido y responsivo para dispositivos móviles» dado el volumen de ~450 turnos mensuales. | G17: En una prueba de reserva de punta a punta desde un dispositivo móvil con conexión 4G, el tiempo entre la selección del horario y la confirmación de la reserva (previo a la redirección a la pasarela de pago) es menor o igual a 5 segundos, medido en tres repeticiones consecutivas. | H17: H-06, H-07 | I17: Pendiente | J17: 2 | K17: Sí | L17: =IF($A17="","",IF(COUNTBLANK($B17:$C17)+COUNTBLANK($E17:$H17)>0,"Faltan campos",IF(AND($C17="No funcional",$D17=""),"Falta categoría",IF($K17="","Falta definir si integra el MVP","Fila completa")))) -> Fila completa
A18: RNF-02 | B18: El sistema debe operar íntegramente desde el navegador web, sin exigir a la clienta la descarga de una aplicación nativa para reservar un turno. | C18: No funcional | D18: Usabilidad | E18: Must | F18: Preferencia relevada explícitamente en las conclusiones del relevamiento (Cap. II.6) y en la entrevista a la clienta frecuente. | G18: Un usuario sin ninguna aplicación instalada además del navegador completa el flujo completo de reserva y pago de seña únicamente accediendo a la URL del sistema, verificable repitiendo la prueba en un dispositivo sin instalaciones adicionales. | H18: H-18 | I18: Validado | J18: 1 | K18: Sí | L18: =IF($A18="","",IF(COUNTBLANK($B18:$C18)+COUNTBLANK($E18:$H18)>0,"Faltan campos",IF(AND($C18="No funcional",$D18=""),"Falta categoría",IF($K18="","Falta definir si integra el MVP","Fila completa")))) -> Fila completa
A19: RNF-03 | B19: El sistema restringe la visibilidad de los datos de alergias o sensibilidad de piel al rol profesional asignado al turno y no los trata como historia clínica. | C19: No funcional | D19: Seguridad | E19: Must | F19: Exigencia normativa directa de la Ley N.º 25.326 (Cap. I.6, I.7, II.5). | G19: Dada una clienta con una advertencia operativa de alergia registrada, cuando una profesional distinta a la asignada al turno consulta el sistema, el dato no aparece en su vista; solo la profesional asignada a ese turno puede visualizarlo, verificable mediante inspección de los permisos de la consulta. | H19: H-13, H-14 | I19: Validado | J19: 2 | K19: Sí | L19: =IF($A19="","",IF(COUNTBLANK($B19:$C19)+COUNTBLANK($E19:$H19)>0,"Faltan campos",IF(AND($C19="No funcional",$D19=""),"Falta categoría",IF($K19="","Falta definir si integra el MVP","Fila completa")))) -> Fila completa
A20: RNF-04 | B20: El sistema delega en una pasarela de pagos certificada toda captura de medios de pago y conserva únicamente el identificador de confirmación (token) que ella devuelve; no almacena datos de tarjetas ni de cuentas bancarias. | C20: No funcional | D20: Cumplimiento normativo | E20: Must | F20: Exigencia explícita de Cap. I.7 / II.5 sobre la relación con la pasarela de pagos; evita exponer a Loren y Kologic a responsabilidad sobre datos financieros de terceros. | G20: Una revisión del esquema de la base de datos del sistema no encuentra ninguna columna que almacene número de tarjeta, código de seguridad o dato bancario de la clienta; el único dato de pago retenido es el identificador de confirmación (token) devuelto por la pasarela, verificable por inspección del esquema. | H20: H-08 | I20: Validado | J20: 2 | K20: Sí | L20: =IF($A20="","",IF(COUNTBLANK($B20:$C20)+COUNTBLANK($E20:$H20)>0,"Faltan campos",IF(AND($C20="No funcional",$D20=""),"Falta categoría",IF($K20="","Falta definir si integra el MVP","Fila completa")))) -> Fila completa
A21: RNF-05 | B21: El sistema debe registrar, con fecha y hora, todo cambio de estado de un turno y toda eliminación o anonimización de datos personales. | C21: No funcional | D21: Cumplimiento normativo | E21: Should | F21: Exigencia del Art. 25 de la Ley N.º 25.326 (Cap. I.6) para sostener la trazabilidad ante una eventual auditoría; no bloquea la operación diaria de reserva. | G21: Dada la anonimización de los datos de una clienta ejecutada por la propietaria, cuando se consulta el registro de auditoría, aparece una entrada con fecha, hora y el alcance de la operación realizada, verificable en dicho registro. | H21: H-16 | I21: Validado | J21: 4 | K21: No | L21: =IF($A21="","",IF(COUNTBLANK($B21:$C21)+COUNTBLANK($E21:$H21)>0,"Faltan campos",IF(AND($C21="No funcional",$D21=""),"Falta categoría",IF($K21="","Falta definir si integra el MVP","Fila completa")))) -> Fila completa
L22: =IF($A22="","",IF(COUNTBLANK($B22:$C22)+COUNTBLANK($E22:$H22)>0,"Faltan campos",IF(AND($C22="No funcional",$D22=""),"Falta categoría",IF($K22="","Falta definir si integra el MVP","Fila completa"))))
L23: =IF($A23="","",IF(COUNTBLANK($B23:$C23)+COUNTBLANK($E23:$H23)>0,"Faltan campos",IF(AND($C23="No funcional",$D23=""),"Falta categoría",IF($K23="","Falta definir si integra el MVP","Fila completa"))))
L24: =IF($A24="","",IF(COUNTBLANK($B24:$C24)+COUNTBLANK($E24:$H24)>0,"Faltan campos",IF(AND($C24="No funcional",$D24=""),"Falta categoría",IF($K24="","Falta definir si integra el MVP","Fila completa"))))
L25: =IF($A25="","",IF(COUNTBLANK($B25:$C25)+COUNTBLANK($E25:$H25)>0,"Faltan campos",IF(AND($C25="No funcional",$D25=""),"Falta categoría",IF($K25="","Falta definir si integra el MVP","Fila completa"))))
L26: =IF($A26="","",IF(COUNTBLANK($B26:$C26)+COUNTBLANK($E26:$H26)>0,"Faltan campos",IF(AND($C26="No funcional",$D26=""),"Falta categoría",IF($K26="","Falta definir si integra el MVP","Fila completa"))))
L27: =IF($A27="","",IF(COUNTBLANK($B27:$C27)+COUNTBLANK($E27:$H27)>0,"Faltan campos",IF(AND($C27="No funcional",$D27=""),"Falta categoría",IF($K27="","Falta definir si integra el MVP","Fila completa"))))
L28: =IF($A28="","",IF(COUNTBLANK($B28:$C28)+COUNTBLANK($E28:$H28)>0,"Faltan campos",IF(AND($C28="No funcional",$D28=""),"Falta categoría",IF($K28="","Falta definir si integra el MVP","Fila completa"))))
L29: =IF($A29="","",IF(COUNTBLANK($B29:$C29)+COUNTBLANK($E29:$H29)>0,"Faltan campos",IF(AND($C29="No funcional",$D29=""),"Falta categoría",IF($K29="","Falta definir si integra el MVP","Fila completa"))))
L30: =IF($A30="","",IF(COUNTBLANK($B30:$C30)+COUNTBLANK($E30:$H30)>0,"Faltan campos",IF(AND($C30="No funcional",$D30=""),"Falta categoría",IF($K30="","Falta definir si integra el MVP","Fila completa"))))
L31: =IF($A31="","",IF(COUNTBLANK($B31:$C31)+COUNTBLANK($E31:$H31)>0,"Faltan campos",IF(AND($C31="No funcional",$D31=""),"Falta categoría",IF($K31="","Falta definir si integra el MVP","Fila completa"))))
L32: =IF($A32="","",IF(COUNTBLANK($B32:$C32)+COUNTBLANK($E32:$H32)>0,"Faltan campos",IF(AND($C32="No funcional",$D32=""),"Falta categoría",IF($K32="","Falta definir si integra el MVP","Fila completa"))))
L33: =IF($A33="","",IF(COUNTBLANK($B33:$C33)+COUNTBLANK($E33:$H33)>0,"Faltan campos",IF(AND($C33="No funcional",$D33=""),"Falta categoría",IF($K33="","Falta definir si integra el MVP","Fila completa"))))
... L201: =IF($A201="","",IF(COUNTBLANK($B201:$C201)+COUNTBLANK($E201:$H201)>0,"Faltan campos",IF(AND($C201="No funcional",$D201=""),"Falta categoría",IF($K201="","Falta definir si integra el MVP","Fila completa"))))

Sheet Trazabilidad
A1: Matriz de trazabilidad · hallazgo de la AE1 → requisito
A2: Se verifica en doble vía. Todo requisito llega a un hallazgo; todo hallazgo llega a un requisito o a una justificación expresa de por qué no derivó ninguno. El silencio no es una decisión.
A4: Código (H-01, H-02…) | B4: Hallazgo de la AE1 (dato y valor) | C4: Fuente (apartado del Cap. II o acta) | D4: Requisito(s) derivado(s) | E4: Si no deriva: justificación | F4: Control de la doble vía
A5: H-01 | B5: Registro de chat de WhatsApp del 24/11/2025: superposición de un turno a las 16:00 h pese a estar confirmado dos semanas antes en el registro físico; el horario seguía figurando disponible por falta de sincronización digital. | C5: Cap. I.1, evidencia fechada | D5: RF-01 | F5: =IF($A5="","",IF(AND($D5="",$E5=""),"Hallazgo sin destino",IF($D5="","Sin requisito, justificado","Deriva requisito"))) -> Deriva requisito
A6: H-02 | B6: Línea de base cuantificada: 10 turnos superpuestos por mes sobre 120 turnos individuales de Loren (8,33% de error), medida entre noviembre de 2025 y julio de 2026 cruzando la agenda de papel con los chats de WhatsApp. | C6: Cap. I.3, línea de base | D6: RF-01 | F6: =IF($A6="","",IF(AND($D6="",$E6=""),"Hallazgo sin destino",IF($D6="","Sin requisito, justificado","Deriva requisito"))) -> Deriva requisito
A7: H-03 | B7: Costo de oportunidad mensual estimado entre $150.000 y $540.000 ARS por clientas que desisten de reservar o reagendar tras un conflicto de agenda. | C7: Cap. I.3, consecuencia acreditada | E7: No deriva un requisito propio: es el impacto económico que sostiene la prioridad «Must» de RF-01, RF-03 y RF-04, no una funcionalidad nueva del sistema. | F7: =IF($A7="","",IF(AND($D7="",$E7=""),"Hallazgo sin destino",IF($D7="","Sin requisito, justificado","Deriva requisito"))) -> Sin requisito, justificado
A8: H-04 | B8: El estudio opera sin ningún sistema de información formal: no existe una base de datos centralizada de clientas, turnos, señas ni profesionales. | C8: Cap. I.3, diagnóstico del SI actual | D8: RF-02, RF-11 | F8: =IF($A8="","",IF(AND($D8="",$E8=""),"Hallazgo sin destino",IF($D8="","Sin requisito, justificado","Deriva requisito"))) -> Deriva requisito
A9: H-05 | B9: El 93,57% (131 de 140) de los establecimientos de estética relevados en Posadas opera sin ningún sistema digital; solo 9 (6,43%) cuentan con web o plataforma propia. | C9: Cap. II.1 y II.5, relevamiento propio en Google Maps, agosto de 2026 | E9: No deriva un requisito: es evidencia de contexto de mercado (PESTEL/FODA) que descarta la presión competitiva como desencadenante, no una funcionalidad del sistema. | F9: =IF($A9="","",IF(AND($D9="",$E9=""),"Hallazgo sin destino",IF($D9="","Sin requisito, justificado","Deriva requisito"))) -> Sin requisito, justificado
A10: H-06 | B10: El estudio recibe entre 20 y 30 mensajes de WhatsApp diarios, en su mayoría consultas repetitivas sobre disponibilidad, precios y señas. | C10: Cap. II.3 y II.5; entrevista a Loren, 26/08/2026 | D10: RNF-01 | F10: =IF($A10="","",IF(AND($D10="",$E10=""),"Hallazgo sin destino",IF($D10="","Sin requisito, justificado","Deriva requisito"))) -> Deriva requisito
A11: H-07 | B11: La conciliación manual de un turno insume entre 10 y 15 minutos por consulta, tomada como línea de base del Objetivo específico N.º 4. | C11: Cap. II.3 | D11: RNF-01 | F11: =IF($A11="","",IF(AND($D11="",$E11=""),"Hallazgo sin destino",IF($D11="","Sin requisito, justificado","Deriva requisito"))) -> Deriva requisito
A12: H-08 | B12: Seña fija de $5.000 ARS para turnos individuales, o del 50% del valor para talleres, cobrada manualmente por transferencia bancaria sin trazabilidad automatizada. | C12: Cap. I.3 y II.3; Anexo I | D12: RF-03, RNF-04 | F12: =IF($A12="","",IF(AND($D12="",$E12=""),"Hallazgo sin destino",IF($D12="","Sin requisito, justificado","Deriva requisito"))) -> Deriva requisito
A13: H-09 | B13: Política de cancelación relevada: devolución total con aviso de 12 horas o más; retención del 100% de la seña con aviso menor a 12 horas o no-show. | C13: Cap. I.6 y II.3 | D13: RF-04 | F13: =IF($A13="","",IF(AND($D13="",$E13=""),"Hallazgo sin destino",IF($D13="","Sin requisito, justificado","Deriva requisito"))) -> Deriva requisito
A14: H-10 | B14: Tolerancia de llegada de 20 minutos desde el horario pactado; superado ese margen, el turno se cancela para no demorar la agenda subsiguiente. | C14: Cap. I.6 y II.3 | D14: RF-05 | F14: =IF($A14="","",IF(AND($D14="",$E14=""),"Hallazgo sin destino",IF($D14="","Sin requisito, justificado","Deriva requisito"))) -> Deriva requisito
A15: H-11 | B15: Hoy Loren asigna a la profesional por antigüedad y disponibilidad, sin asignación automática (entrevista a Loren); el sistema debe asignar automáticamente, cuando la clienta no elige una en particular, a la profesional libre con menos turnos en la semana y, a igual carga, a la de mayor antigüedad. | C15: Cap. I.6, módulos funcionales; Anexo I, entrevista a Loren | D15: RF-06 | F15: =IF($A15="","",IF(AND($D15="",$E15=""),"Hallazgo sin destino",IF($D15="","Sin requisito, justificado","Deriva requisito"))) -> Deriva requisito
A16: H-12 | B16: Distintos tipos de servicio requieren datos específicos (uñas: cantidad y reconstrucción; cabello: largo y extensiones; rostro: tipo de piel), y permiten adjuntar imágenes o textos de referencia. | C16: Cap. I.6 | E16: No deriva un requisito propio de este catálogo: son variantes de captura de datos por categoría de servicio que se resuelven en el diseño del formulario de reserva, no una restricción de negocio autónoma. | F16: =IF($A16="","",IF(AND($D16="",$E16=""),"Hallazgo sin destino",IF($D16="","Sin requisito, justificado","Deriva requisito"))) -> Sin requisito, justificado
A17: H-13 | B17: La información de alergias y tipo de piel hoy se releva de forma verbal e informal, sin ningún registro sistemático. | C17: Cap. II.6, conclusiones del relevamiento | D17: RF-07, RNF-03 | F17: =IF($A17="","",IF(AND($D17="",$E17=""),"Hallazgo sin destino",IF($D17="","Sin requisito, justificado","Deriva requisito"))) -> Deriva requisito
A18: H-14 | B18: Exigencia de consentimiento diferenciado para guardar datos de alergias o piel sensible, conforme a la Ley N.º 25.326. | C18: Cap. I.6 y I.7 | D18: RF-07, RNF-03 | F18: =IF($A18="","",IF(AND($D18="",$E18=""),"Hallazgo sin destino",IF($D18="","Sin requisito, justificado","Deriva requisito"))) -> Deriva requisito
A19: H-15 | B19: Exigencia de exponer la política de privacidad antes de registrar datos personales, con registro de fecha, hora y versión aceptada. | C19: Cap. I.6, Ley N.º 25.326 Art. 25 | D19: RF-08 | F19: =IF($A19="","",IF(AND($D19="",$E19=""),"Hallazgo sin destino",IF($D19="","Sin requisito, justificado","Deriva requisito"))) -> Deriva requisito
A20: H-16 | B20: Exigencia de que la propietaria pueda eliminar o anonimizar datos personales a pedido de la titular, con constancia de auditoría, preservando solo los registros contables o fiscales exigidos. | C20: Cap. I.6 y I.7, Ley N.º 25.326 Art. 25 | D20: RF-09, RNF-05 | F20: =IF($A20="","",IF(AND($D20="",$E20=""),"Hallazgo sin destino",IF($D20="","Sin requisito, justificado","Deriva requisito"))) -> Deriva requisito
A21: H-17 | B21: Existencia de servicios simultáneos con dos profesionales distintas, hoy coordinados de forma manual y verbal entre ellas. | C21: Anexo I, entrevista a Loren | D21: RF-10 | F21: =IF($A21="","",IF(AND($D21="",$E21=""),"Hallazgo sin destino",IF($D21="","Sin requisito, justificado","Deriva requisito"))) -> Deriva requisito
A22: H-18 | B22: Preferencia relevada de las clientas por un flujo web liviano desde el navegador, sin descarga de aplicaciones nativas. | C22: Cap. II.6, conclusiones del relevamiento | D22: RNF-02 | F22: =IF($A22="","",IF(AND($D22="",$E22=""),"Hallazgo sin destino",IF($D22="","Sin requisito, justificado","Deriva requisito"))) -> Deriva requisito
A23: H-19 | B23: Catálogo de servicios organizado en cuatro categorías (uñas, cabello, cuerpo, rostro), con precios y duraciones diferenciados por técnica, hoy no sistematizado en ningún registro único. | C23: Cap. II.3, síntesis del catálogo relevado | D23: RF-11 | F23: =IF($A23="","",IF(AND($D23="",$E23=""),"Hallazgo sin destino",IF($D23="","Sin requisito, justificado","Deriva requisito"))) -> Deriva requisito
A24: H-20 | B24: El estudio atiende de forma autónoma a partir de los 13 años; para menores de 13, la reserva y gestión del turno la realiza exclusivamente la madre, padre o tutor, sin registrar datos identificatorios de la menor. | C24: Cap. I.7, atención de menores y registro de acompañantes | D24: RF-12 | F24: =IF($A24="","",IF(AND($D24="",$E24=""),"Hallazgo sin destino",IF($D24="","Sin requisito, justificado","Deriva requisito"))) -> Deriva requisito
A25: H-21 | B25: Ocho plataformas genéricas de reserva evaluadas y descartadas (ReservaSimple, Agenda+, AgendaPro, WeiBook, MiAgendaProfesional, Tiska, Turnau, Booksy) por costos dolarizados o suscripciones fijas inviables, y por no adaptarse al esquema local de alquiler más comisión. | C25: Cap. I.4 | E25: No deriva un requisito: es la evidencia que sostiene la decisión de construir un sistema a medida en vez de adoptar una plataforma genérica, no una funcionalidad concreta de Nexa. | F25: =IF($A25="","",IF(AND($D25="",$E25=""),"Hallazgo sin destino",IF($D25="","Sin requisito, justificado","Deriva requisito"))) -> Sin requisito, justificado
F26: =IF($A26="","",IF(AND($D26="",$E26=""),"Hallazgo sin destino",IF($D26="","Sin requisito, justificado","Deriva requisito")))
F27: =IF($A27="","",IF(AND($D27="",$E27=""),"Hallazgo sin destino",IF($D27="","Sin requisito, justificado","Deriva requisito")))
F28: =IF($A28="","",IF(AND($D28="",$E28=""),"Hallazgo sin destino",IF($D28="","Sin requisito, justificado","Deriva requisito")))
F29: =IF($A29="","",IF(AND($D29="",$E29=""),"Hallazgo sin destino",IF($D29="","Sin requisito, justificado","Deriva requisito")))
F30: =IF($A30="","",IF(AND($D30="",$E30=""),"Hallazgo sin destino",IF($D30="","Sin requisito, justificado","Deriva requisito")))
F31: =IF($A31="","",IF(AND($D31="",$E31=""),"Hallazgo sin destino",IF($D31="","Sin requisito, justificado","Deriva requisito")))
F32: =IF($A32="","",IF(AND($D32="",$E32=""),"Hallazgo sin destino",IF($D32="","Sin requisito, justificado","Deriva requisito")))
F33: =IF($A33="","",IF(AND($D33="",$E33=""),"Hallazgo sin destino",IF($D33="","Sin requisito, justificado","Deriva requisito")))
F34: =IF($A34="","",IF(AND($D34="",$E34=""),"Hallazgo sin destino",IF($D34="","Sin requisito, justificado","Deriva requisito")))
F35: =IF($A35="","",IF(AND($D35="",$E35=""),"Hallazgo sin destino",IF($D35="","Sin requisito, justificado","Deriva requisito")))
F36: =IF($A36="","",IF(AND($D36="",$E36=""),"Hallazgo sin destino",IF($D36="","Sin requisito, justificado","Deriva requisito")))
F37: =IF($A37="","",IF(AND($D37="",$E37=""),"Hallazgo sin destino",IF($D37="","Sin requisito, justificado","Deriva requisito")))
... F61: =IF($A61="","",IF(AND($D61="",$E61=""),"Hallazgo sin destino",IF($D61="","Sin requisito, justificado","Deriva requisito")))

Sheet Entidades
A1: Lista filtrada de entidades del dominio · Instrumento 28
A2: Cada candidata pasa por el filtro de las tres preguntas. Las descartadas no se borran: se reclasifican, porque los descartes de hoy son las preguntas del glosario de mañana.
A4: Candidata (sustantivo de la organización) | B4: ¿Identidad propia? | C4: ¿Datos y reglas propios? | D4: ¿Dentro del recorte? | E4: Veredicto | F4: Fuente que la acredita | G4: Relaciones principales
A5: Turno | B5: Sí | C5: Sí | D5: Sí | E5: Entidad | F5: Cap. I.6, módulos funcionales; Cap. I.3, línea de base de turnos superpuestos | G5: Un turno pertenece a una clienta y a una profesional; puede agruparse con otros turnos simultáneos de la misma reserva.
A6: Profesional | B6: Sí | C6: Sí | D6: Sí | E6: Entidad | F6: Cap. II.3, capacidad operativa (7 profesionales); Anexo I, entrevista a Loren | G6: Una profesional atiende muchos turnos; ofrece uno o varios servicios del catálogo.
A7: Clienta | B7: Sí | C7: Sí | D7: Sí | E7: Entidad | F7: Cap. I.6, captura de información en el registro; Cap. II.1, fuentes primarias | G7: Una clienta reserva muchos turnos; puede tener observaciones operativas asociadas.
A8: Servicio | B8: Sí | C8: Sí | D8: Sí | E8: Entidad | F8: Cap. II.3, síntesis del catálogo relevado (uñas, cabello, cuerpo, rostro) | G8: Un servicio pertenece a una categoría; es ofrecido por una o varias profesionales; es elegido en muchos turnos.
A9: Producto | B9: Sí | C9: Sí | D9: Sí | E9: Entidad | F9: Cap. I.5, descripción breve del sistema de información («comprar productos») | G9: Un producto puede incluirse en muchos pedidos de la tienda.
A10: Promoción | B10: Sí | C10: Sí | D10: Sí | E10: Entidad | F10: Cap. I.5, descripción breve del sistema de información («crear promociones») | G10: Una promoción se aplica sobre uno o varios servicios o productos.
A11: Categoría de servicio | B11: Parcialmente | C11: No | D11: Sí | E11: Atributo de otra entidad | F11: Cap. II.3, síntesis del catálogo relevado (cuatro categorías: uñas, cabello, cuerpo, rostro) | G11: Clasifica al Servicio; no tiene reglas de negocio propias más allá de agrupar.
A12: Seña | B12: No | C12: Sí | D12: Sí | E12: Atributo de otra entidad | F12: Cap. I.6, cobro de la seña; Cap. II.3, condiciones financieras y señas | G12: No existe sin un Turno asociado; hereda su estado del ciclo de vida del turno.
A13: Establecimiento (Loren) | B13: Parcialmente | C13: Sí | D13: Sí | E13: Producto del sistema | F13: Cap. I.1, origen del proyecto; Anexo III, ADR-001 sobre arquitectura single-tenant | G13: Es la configuración global de esta instancia; no tiene múltiples ejemplares dentro de este sistema.
A14: WhatsApp | B14: Sí | C14: No | D14: No | E14: Elemento del entorno | F14: Cap. I.6, exclusiones declaradas; Anexo II, nota aclaratoria sobre el ícono flotante | G14: Canal externo de contacto institucional; queda fuera de la arquitectura de reserva de Nexa.
A15: Cuaderno físico de turnos | B15: Sí | C15: Sí | D15: No | E15: Elemento del entorno | F15: Cap. I.1, origen del proyecto; Cap. I.3, diagnóstico del sistema de información actual | G15: Es la fuente de verdad actual que Nexa reemplaza; no se digitaliza ni se migra al sistema.
... A19: Evento especial | B19: Sí | C19: Sí | D19: Sí | E19: Entidad | F19: Modelo SpecialEvent del backend, commit 1c90c9b (14/09/2026). Función construida durante el desarrollo; no tiene requisito asociado. | G19: Un evento especial se muestra en el home y se puede reservar sin elegir zonas; no reutiliza el indicador de servicio especial.

Sheet Reglas
A1: Registro de reglas de negocio · Instrumento 29
A2: Regla y requisito derivado deben citar la misma fuente: esa coincidencia es la trazabilidad que la dimensión 1 de la rúbrica verifica.
A4: Código | B4: Tipo | C4: Enunciado verificable | D4: Fuente | E4: Estado | F4: Requisito derivado (ID)
A5: R-01 | B5: Restricción | C5: No se puede confirmar la reserva de un turno si la profesional seleccionada ya tiene otro turno activo (no cancelado) el mismo día y a la misma hora de inicio, dentro de las franjas de atención que ella define. | D5: Cap. I.3, primer requisito derivado; Cap. II.6, conclusiones del relevamiento | E5: Validada | F5: RF-01
A6: R-02 | B6: Restricción | C6: Si la cancelación se notifica con menos de 12 horas de anticipación al turno, o ante inasistencia (no-show), la seña queda retenida en su totalidad; con 12 horas o más, corresponde la devolución total. | D6: Cap. I.6, módulos funcionales | E6: Validada | F6: RF-04
A7: R-03 | B7: Restricción | C7: Si transcurren más de 20 minutos desde el horario pactado sin que la clienta se presente, el turno se cancela automáticamente y el horario queda disponible para reasignarse. | D7: Cap. I.6; Cap. II.3, tolerancia de llegada | E7: Validada | F7: RF-05
A8: R-04 | B8: Derivación | C8: Cuando la clienta no indica preferencia por una profesional, el sistema asigna automáticamente el turno entre las profesionales activas, habilitadas para el servicio, con disponibilidad ese día y hora y sin otro turno activo a esa hora de inicio. Elige la que registre menos turnos no cancelados ni no-show en la semana de la fecha pedida (lunes a domingo); a igual cantidad, la de mayor antigüedad. Si ninguna está libre, informa que el horario no está disponible. | D8: Cap. I.6, módulos funcionales; criterio de antigüedad según respuesta de Loren (Bitácora, entrada del 02/09/2026). Implementado en resolveProfessionalId (appointment.service.ts), commit c12671b. Falta la confirmación escrita de Loren sobre el criterio de menor carga semanal. | E8: Validada | F8: RF-06
A9: R-05 | B9: Restricción | C9: El sistema no guarda ningún dato de alergias o sensibilidad de piel de la clienta sin su consentimiento explícito y diferenciado para ese campo. | D9: Cap. I.6 y I.7, cumplimiento de la Ley N.º 25.326 | E9: Validada | F9: RF-07
A10: R-06 | B10: Existencia | C10: Toda reserva de un turno para una clienta menor de 13 años debe quedar asociada a la gestión de una madre, padre o tutor legal; el sistema registra solo la condición de acompañante y su vínculo, sin datos identificatorios de la menor. | D10: Cap. I.7, atención de menores y registro de acompañantes | E10: Validada | F10: RF-12
A11: R-07 | B11: Derivación | C11: El monto de la seña lo define la propietaria en Configuración, como un monto fijo en pesos o como un porcentaje del valor del servicio (hoy $5.000 ARS). Para una reserva con servicios simultáneos de profesionales distintas (combo) se cobra una sola seña, que vale para todos los servicios y todas las profesionales. | D11: Cap. II.3, condiciones financieras y señas; Anexo I; Configuración del sistema (valor que fija la propietaria). | E11: Validada | F11: RF-03
A12: R-08
A13: R-09
A14: R-10
A15: R-11
A16: R-12
A17: R-13
A18: R-14
A19: R-15
A20: R-16
A21: R-17
A22: R-18
A23: R-19
... A40: R-36

Sheet Límites
A1: Límites del proyecto · apartado III.4 del informe
A2: Seis exclusiones declaradas por escrito. Una exclusión decidida sin el referente es una hipótesis; validada y con acta, es una frontera real.
A4: Código | B4: Qué queda fuera | C4: Motivo | D4: Quién lo valida | E4: Estado | F4: Fuente
A5: L-01 | B5: Facturación electrónica y módulo contable completo | C5: Excede el alcance formativo de un Proyecto Integrador Final individual. | D5: Loren (referente) | E5: Validado en la sesión del prototipo v0 (28/08/2026) | F5: Cap. I.6, exclusiones declaradas
A6: L-02 | B6: Liquidación de la comisión entre el estudio y las profesionales (el 80/20 que Loren calcula hoy) | C6: El sistema no tiene ninguna regla, módulo contable ni de liquidación de comisiones: Loren lo sigue haciendo fuera de Nexa. | D6: Loren (referente) | E6: Pendiente de validación con la referente | F6: Cap. II.3, variabilidad de ingresos y esquemas de prestación
A7: L-03 | B7: Chatbot de WhatsApp y reserva por WhatsApp | C7: No hay chatbot de WhatsApp ni se va a desarrollar. La reserva se hace solo por la web; WhatsApp se usa como enlace de contacto, para coordinar el pago de la seña y para avisar de una devolución. | D7: Loren (referente) | E7: Validado en la sesión del prototipo v0 (28/08/2026) | F7: Cap. I.6, exclusiones declaradas; Anexo II
A8: L-04 | B8: Panel de administración SaaS multi-tenant centralizado | C8: La arquitectura es de instancia única duplicable (ADR-001); el panel centralizado no se construye en esta etapa. | D8: Autora | E8: Decisión de arquitectura de la autora (ADR-001) | F8: Anexo III, ADR-001
A9: L-05 | B9: Tratamiento de alergias y piel sensible como dato de salud | C9: Se limita a una advertencia operativa del servicio, no a historia clínica, para acotar el régimen de responsabilidad (RNF-03). | D9: Loren (referente) | E9: Validado en la sesión del prototipo v0 (28/08/2026) | F9: Cap. I.7; Anexo II
A10: L-06 | B10: Talleres y capacitaciones | C10: El sistema no tiene talleres y todavía no se van a incluir. La seña es única y la define la propietaria en Configuración. | D10: Loren (referente) | E10: Pendiente de validación con la referente | F10: Anexo I, entrevista a Loren

Sheet Glosario
A1: Glosario del dominio · Instrumento 30
A2: Vocabulario normativo del informe completo y, más adelante, de las tablas del sistema. La entrada más valiosa es la del término en disputa: el que dos personas de la organización usan distinto.
A4: Término (como lo usa la organización) | B4: Definición operativa (una o dos oraciones) | C4: Sinónimos y falsos amigos detectados | D4: Fuente (quién lo usa así) | E4: ¿En disputa?
A5: Turno | B5: Reserva de un bloque horario de un servicio con una profesional para una clienta determinada. | C5: En el informe y las entrevistas se usa indistintamente «turno» y «reserva»; no se relevó el término «cita», aunque podría aparecer en otros estudios del rubro. | D5: Cap. I.1, I.5 y II.3 | E5: No
A6: Seña | B6: Pago parcial que la clienta abona para reservar el turno, como garantía de la reserva. Su monto lo define la propietaria en Configuración (en pesos o como porcentaje del servicio; hoy $5.000). Se paga con Mercado Pago (hoy en modo prueba, con tarjeta de prueba) o se coordina por WhatsApp; el turno queda confirmado aunque la seña esté pendiente, hasta que se acredita o la propietaria la marca como pagada. En una reserva con servicios simultáneos se cobra una sola seña. | C6: El Anexo I usa además «anticipo» para referirse al mismo concepto; el Anexo II usa «seña obligatoria». | D6: Cap. I.6, II.3 y Anexo I | E6: No
A7: No-show | B7: Inasistencia de la clienta al turno sin aviso previo, más allá de la tolerancia de 20 minutos, que determina la retención total de la seña. | C7: El informe usa «inasistencia» y «no-show» como sinónimos exactos. | D7: Cap. I.6 | E7: No
A8: Advertencia operativa | B8: Dato de alergia o sensibilidad de piel de la clienta, registrado para uso técnico de la profesional durante la prestación, expresamente diferenciado de un dato de salud o historia clínica. | C8: No debe confundirse con «dato de salud» en el sentido de la Ley N.º 25.326; el informe hace explícita esta distinción para acotar el riesgo legal. | D8: Cap. I.6, I.7 y II.5 | E8: No
A9: Instancia dedicada (single-tenant) | B9: Arquitectura en la que cada estudio cliente de Kologic opera en su propio entorno y base de datos independiente, sin compartir infraestructura con otros clientes. | C9: La Bitácora registra que el proyecto arrancó pensado como «multi-tenant SaaS» y fue reemplazado por este modelo; ambos términos aparecen en distintos documentos según la etapa del proyecto. | D9: Resumen del informe; Anexo III, ADR-001 | E9: No
A10: Responsable / Encargado del Tratamiento | B10: Roles definidos por el Art. 25 de la Ley N.º 25.326: Loren es la Responsable (titular que determina la finalidad de los datos); Kologic es la Encargada (provee la infraestructura sin fines propios sobre esos datos). | C10: — | D10: Cap. I.7 | E10: No

Sheet Reuniones y datos
A1: Reuniones con la referente y datos del relevamiento
A2: Fechas y valores del relevamiento de la AE1 y de las reuniones posteriores, para que el informe, la bitácora y el libro cuenten lo mismo.
A4: Reunión o dato | B4: Fecha o valor | C4: Detalle | D4: Fuente
A5: Reunión de relevamiento del problema | B5: Junio de 2026 | C5: Reunión sencilla, solo para conocer el problema que tenía Loren. | D5: Recursos, categoría 1
A6: Entrevistas y toma de datos | B6: 26/08/2026 | C6: Entrevista de 45 minutos a Loren y entrevista de 20 minutos a una profesional; observación directa de la agenda de papel. | D6: Cap. II.2 y II.3
A7: Muestra del prototipo v0 | B7: 28/08/2026 | C7: Validación del prototipo de baja fidelidad con Loren. | D7: Cap. I.6
A8: Muestra del prototipo v2 y aprobación | B8: 28/09/2026 | C8: Reunión presencial: se mostró toda la página y Loren no pidió ningún cambio. Acta del 28/09. | D8: Acta de la sesión de validación
A9: Período del registro manual analizado | B9: Noviembre de 2025 a julio de 2026 | C9: Se vieron los chats de WhatsApp y la agenda de papel. | D9: Cap. I.3, línea de base
A10: Chat que muestra la superposición | B10: 24/11/2025 | C10: Conversación de WhatsApp de Loren con una clienta en la que se superpusieron los turnos. | D10: Cap. I.1, evidencia fechada
A11: Fecha de creación de Loren Estudio de Belleza | B11: 01/09/2025 | C11: Apertura del estudio. | D11: Cap. I.1
A12: Horario de atención | B12: Lunes a sábado, de 8:00 a 20:00 | C12: Horario general del estudio; cada profesional define las franjas en que atiende. | D12: Cap. II.3
A13: Plazo para cancelar y recibir la devolución de la seña | B13: 12 horas | C13: Con 12 horas o más de aviso se devuelve la seña; con menos, o por inasistencia, se retiene. | D13: Cap. II.3; R-02

Sheet Iteraciones
A1: Plan de iteraciones y presupuesto de horas · Capítulo V
A2: El cronograma se construye sobre el presupuesto efectivo de horas-persona y se alinea con la cadencia de artefactos: v1 en la semana 8, v2 en la semana 11, v3 en la semana 13 y versión funcional congelada en la semana 14.
A4: Iteración | B4: Desde | C4: Hasta | D4: Objetivo verificable | E4: Requisitos comprometidos (ID) | F4: Entregable de cierre | G4: Horas asignadas
A5: 1 | B5: Semana 6 | C5: Semana 8 | D5: Prototipo v1 ejecutable: alta de cuenta, catálogo de servicios, reserva con validación de disponibilidad en tiempo real y aceptación registrada de la política de privacidad. | E5: RF-01, RF-02, RF-08, RF-11, RNF-02 | F5: Repositorio etiquetado v1, clonable y ejecutable siguiendo el archivo de lectura. | G5: 70
A6: 2 | B6: Semana 9 | C6: Semana 11 | D6: v2: cobro de seña mediante Mercado Pago (modo prueba) o coordinada por WhatsApp, política de cancelación con devolución o retención, consentimiento diferenciado para datos de alergias y restricción de su visibilidad a la profesional asignada, y registro de acompañante para menores de 13 años. | E6: RF-03, RF-04, RF-07, RF-12, RNF-01, RNF-03, RNF-04 | F6: v2 con el flujo de pago de la seña funcionando de punta a punta. | G6: 70
A7: 3 | B7: Semana 12 | C7: Semana 13 | D7: v3: asignación automática de profesional por disponibilidad y menor carga semanal, con desempate por antigüedad; tolerancia de 20 minutos con liberación automática del horario, y reserva de servicios simultáneos con profesionales distintas. | E7: RF-05, RF-06, RF-10 | F7: v3 con las reglas de agenda avanzada validadas con la propietaria. | G7: 35
A8: 4 | B8: Semana 14 | C8: Semana 14 | D8: Versión funcional congelada: eliminación o anonimización de datos a pedido de la titular y registro de auditoría de cambios sensibles. | E8: RF-09, RNF-05 | F8: Versión congelada etiquetada, lista para evaluación. | G8: 25
A9: 5
A10: 6
A11: 7
A12: 8
A15: Presupuesto de horas-persona
A16: Integrantes del equipo | B16: 1
A17: Horas semanales reales por integrante (declaradas, no deseadas) | B17: 25
A18: Semanas del período | B18: 9
A19: Presupuesto total | B19: =IF(COUNT(B16:B18)=3,B16*B17*B18,"") -> 225
A20: Reducción prevista por exámenes y feriados (horas) | B20: 15
A21: Presupuesto efectivo resultante | B21: =IF(B19="","",B19-N(B20)) -> 210
A22: Horas ya asignadas a iteraciones | B22: =SUM(G5:G12) -> 200
A23: Margen disponible | B23: =IF(B21="","",B21-B22) -> 10
A25: Cláusula de contingencia (exigencia vii de la consigna)
A26: Si el presupuesto de horas cae un tercio, se posterga | B26: la Iteración 4 (versión funcional congelada, 25 h) y la Iteración 3 (agenda avanzada, 35 h) completas; sumadas a las 10 h de margen cubren las 70 h perdidas. Sus requisitos —RF-05, RF-06, RF-09, RF-10 y RNF-05— pasan a una segunda etapa posterior a la evaluación de la AE2, ya que ninguno integra el MVP definido en el apartado V.5.
A27: Criterio de redistribución, según el acta de constitución | B27: Se prioriza sostener los requisitos «Must» que integran el MVP (RF-01 a RF-04, RF-07, RF-08, RF-11, RF-12 y RNF-01 a RNF-04). Los requisitos «Should» de las Iteraciones 3 y 4 se redistribuyen o postergan primero, empezando por la iteración de fecha más lejana.
A28: Qué no se sacrifica en ningún caso | B28: La trazabilidad del catálogo y la ejecutabilidad del prototipo v1: son condiciones de cómputo.

Sheet Recursos
A1: Dimensionamiento de recursos y estructura de costos · Capítulo X
A2: Cada asignación con su justificación y su fuente. Toda cifra de costo responde las tres preguntas: quién la produjo, con qué método y sobre qué universo, y para qué período de referencia. No se promedian cifras de universos distintos. Importes en pesos argentinos (ARS) y en dólares estadounidenses (USD): los bienes comprados en dólares se valúan al tipo de cambio de su fecha; el resto se convierte al tipo de cambio minorista de referencia del BCRA, $1.545,118 (cotización vendedor, 25/09/2026, 15:00 h).
A4: Clase de recurso | B4: Concepto | C4: Cantidad | D4: Unidad | E4: Costo unitario (ARS) | F4: Costo unitario (USD) | G4: Subtotal (ARS) | H4: Subtotal (USD) | I4: Naturaleza | J4: Fuente, período y justificación
A5: 1. Costos directos (relacionados directamente con el desarrollo)
A6: 1.1 Personal técnico
A7: Humanos | B7: Desarrollo, pruebas y documentación del sistema Nexa (autora) | C7: =$C$77-$C$78-$C$79 -> 193 | D7: hora | E7: =$C$76 -> 21600 | F7: =IF(E7="","",E7/$C$74) -> 13.979515 | G7: =IF(OR(C7="",E7=""),"",C7*E7) -> 4168800 | H7: =IF(OR(C7="",F7=""),"",C7*F7) -> 2698.0464 | I7: OPEX | J7: Costo de oportunidad de referencia, no pago real, ya que el proyecto es propio y no se factura a la organización. Las horas del período de desarrollo (200) son una estimación e incluyen desarrollo, reuniones, capacitación y documentación; esta fila recibe el saldo tras restar las reuniones y la capacitación. El mantenimiento posterior al lanzamiento se presupuesta aparte (categoría 5). Tarifa: ver parámetros.
A8: Humanos | B8: Reuniones presenciales con la referente (relevamiento, entrevistas, prototipo v0 y validación del prototipo v2) | C8: =$C$78 -> 3 | D8: hora | E8: =$C$76 -> 21600 | F8: =IF(E8="","",E8/$C$74) -> 13.979515 | G8: =IF(OR(C8="",E8=""),"",C8*E8) -> 64800 | H8: =IF(OR(C8="",F8=""),"",C8*F8) -> 41.938544 | I8: OPEX | J8: Tiempo de la autora en las cuatro reuniones presenciales con la propietaria de Loren Estudio de Belleza (relevamiento del problema en junio, entrevistas y toma de datos el 26/08, muestra del prototipo v0 el 28/08 y validación del prototipo v2 el 28/09 de 2026), 3 horas en total. Incluidas en las horas totales del período de desarrollo. Valuadas a la misma tarifa por hora que el desarrollo.
A9: Humanos | B9: Capacitación de Loren y las profesionales en el uso del sistema (prevista, aún no realizada) | C9: =$C$79 -> 4 | D9: hora | E9: =$C$76 -> 21600 | F9: =IF(E9="","",E9/$C$74) -> 13.979515 | G9: =IF(OR(C9="",E9=""),"",C9*E9) -> 86400 | H9: =IF(OR(C9="",F9=""),"",C9*F9) -> 55.918059 | I9: OPEX | J9: Sesión de capacitación dictada por la autora antes de la puesta en operación. Incluida en las horas totales del período de desarrollo. Valuada a la misma tarifa por hora; no es un pago efectivo.
A10: 1.2 Licencias y herramientas de desarrollo
A11: Tecnológicos | B11: Backend | C11: 1 | D11: licencia | E11: 0 | F11: =IF(E11="","",E11/$C$74) -> 0 | G11: =IF(OR(C11="",E11=""),"",C11*E11) -> 0 | H11: =IF(OR(C11="",F11=""),"",C11*F11) -> 0 | I11: OPEX | J11: Software de código abierto bajo licencia MIT, sin costo de adquisición ni de uso.
A12: Tecnológicos | B12: Frontend | C12: 1 | D12: licencia | E12: 0 | F12: =IF(E12="","",E12/$C$74) -> 0 | G12: =IF(OR(C12="",E12=""),"",C12*E12) -> 0 | H12: =IF(OR(C12="",F12=""),"",C12*F12) -> 0 | I12: OPEX | J12: Software de código abierto bajo licencia MIT, sin costo de adquisición ni de uso.
A13: Tecnológicos | B13: Entorno de desarrollo (Visual Studio Code) | C13: 1 | D13: licencia | E13: 0 | F13: =IF(E13="","",E13/$C$74) -> 0 | G13: =IF(OR(C13="",E13=""),"",C13*E13) -> 0 | H13: =IF(OR(C13="",F13=""),"",C13*F13) -> 0 | I13: OPEX | J13: Distribución gratuita de Microsoft, utilizada como editor de código durante todo el desarrollo.
A14: Tecnológicos | B14: Control de versiones (GitHub) | C14: 1 | D14: plan | E14: 0 | F14: =IF(E14="","",E14/$C$74) -> 0 | G14: =IF(OR(C14="",E14=""),"",C14*E14) -> 0 | H14: =IF(OR(C14="",F14=""),"",C14*F14) -> 0 | I14: OPEX | J14: Plan gratuito. Los repositorios nexa-frontend y nexa-backend son públicos y sin costo.
A15: Tecnológicos | B15: Integración continua (GitHub Actions) | C15: 1 | D15: plan | E15: 0 | F15: =IF(E15="","",E15/$C$74) -> 0 | G15: =IF(OR(C15="",E15=""),"",C15*E15) -> 0 | H15: =IF(OR(C15="",F15=""),"",C15*F15) -> 0 | I15: OPEX | J15: Minutos de ejecución gratuitos incluidos en el plan free de GitHub.
A16: Tecnológicos | B16: Asistente de programación (Claude Pro) | C16: 2 | D16: mes | E16: 32704.46 | F16: 20 | G16: =IF(OR(C16="",E16=""),"",C16*E16) -> 65408.92 | H16: =IF(OR(C16="",F16=""),"",C16*F16) -> 40 | I16: OPEX | J16: Suscripción de USD 20 por mes, pagada en agosto y septiembre de 2026 con Mercado Pago en pesos argentinos: $32.704,46 por cada cobro (≈ $1.635 por USD, con impuestos incluidos). Su uso se declara en la bitácora y en el informe, con el alcance de lo asistido, según el Protocolo de Uso Autorizado. Fuente: comprobantes de pago de Mercado Pago.
A17: 1.3 Traslados para reuniones presenciales
A18: Otros | B18: Traslado en auto: relevamiento del problema (junio 2026) | C18: =$C$84/$C$85 -> 0.20869565 | D18: litro | E18: =(2180+2217)/2 -> 2198.5 | F18: =IF(E18="","",E18/$C$74) -> 1.4228687 | G18: =IF(OR(C18="",E18=""),"",C18*E18) -> 458.81739 | H18: =IF(OR(C18="",F18=""),"",C18*F18) -> 0.29694651 | I18: OPEX | J18: Domicilio de la autora a Loren Estudio de Belleza: 1,2 km por tramo, en Renault Kwid 1.0 (2018); 2,4 km por reunión a 11,5 km/l. Precio del litro: promedio del rango informado para nafta súper YPF en Posadas a mediados de 2026 ($2.180 a $2.217).
A19: Otros | B19: Traslado en auto: entrevistas y toma de datos (26/08/2026) | C19: =$C$84/$C$85 -> 0.20869565 | D19: litro | E19: =(2180+2217)/2 -> 2198.5 | F19: =IF(E19="","",E19/$C$74) -> 1.4228687 | G19: =IF(OR(C19="",E19=""),"",C19*E19) -> 458.81739 | H19: =IF(OR(C19="",F19=""),"",C19*F19) -> 0.29694651 | I19: OPEX | J19: Mismo trayecto y vehículo. Precio del litro: promedio del rango informado para nafta súper YPF en Posadas antes del aumento de septiembre de 2026 ($2.180 a $2.217), igual que el traslado de junio.
A20: Otros | B20: Traslado en auto: muestra del prototipo v0 a la propietaria (28/08/2026) | C20: =$C$84/$C$85 -> 0.20869565 | D20: litro | E20: =(2180+2217)/2 -> 2198.5 | F20: =IF(E20="","",E20/$C$74) -> 1.4228687 | G20: =IF(OR(C20="",E20=""),"",C20*E20) -> 458.81739 | H20: =IF(OR(C20="",F20=""),"",C20*F20) -> 0.29694651 | I20: OPEX | J20: Mismo trayecto, vehículo y rendimiento que los demás traslados. Precio del litro: promedio del rango informado para nafta súper YPF en Posadas antes del aumento de septiembre de 2026 ($2.180 a $2.217), igual que el traslado de junio.
B21: Subtotal categoría 1 | G21: =SUM(G6:G20) -> 4386785.4 | H21: =SUM(H6:H20) -> 2836.7938
A22: 2. Costos indirectos (gastos generales)
A23: 2.1 Infraestructura y servicios del lugar de trabajo
A24: Tecnológicos | B24: Internet (plan hogareño usado durante el desarrollo) | C24: =$C$77 -> 200 | D24: hora | E24: =$C$86/$C$80 -> 53.312514 | F24: =IF(E24="","",E24/$C$74) -> 0.034503846 | G24: =IF(OR(C24="",E24=""),"",C24*E24) -> 10662.503 | H24: =IF(OR(C24="",F24=""),"",C24*F24) -> 6.9007692 | I24: OPEX | J24: Costo por hora = importe mensual del servicio de internet ÷ 720 horas del mes, por las horas de desarrollo. Se toma solo el renglón de Internet de la factura de Claro ($38.385,01 con la bonificación del 65% por 6 meses; el precio de lista es $109.671,47); se descartan telefonía fija y TV.
A25: Físicos y materiales | B25: Energía eléctrica (consumo del equipo durante el desarrollo) | C25: =IF($C$89="","",$C$89/1000*$C$77) -> 20 | D25: kWh | E25: =IF(OR($C$87="",$C$88=""),"",$C$87/$C$88) -> 254.97401 | F25: =IF(E25="","",E25/$C$74) -> 0.16501912 | G25: =IF(OR(C25="",E25=""),"",C25*E25) -> 5099.4802 | H25: =IF(OR(C25="",F25=""),"",C25*F25) -> 3.3003824 | I25: OPEX | J25: Cantidad = kWh consumidos por el equipo = (potencia en W ÷ 1000) × horas de desarrollo. Costo unitario = tarifa efectiva = importe total de la factura ÷ kWh facturados. Fuente: factura de energía eléctrica del período de desarrollo.
A26: Otros | B26: Agua (gasto general del hogar durante el desarrollo) | C26: =$C$77 -> 200 | D26: hora | E26: =IF(OR($C$90="",$C$91=""),"",$C$90/$C$91/$C$80) -> 29.861111 | F26: =IF(E26="","",E26/$C$74) -> 0.019326104 | G26: =IF(OR(C26="",E26=""),"",C26*E26) -> 5972.2222 | H26: =IF(OR(C26="",F26=""),"",C26*F26) -> 3.8652208 | I26: OPEX | J26: Imputación proporcional de un gasto general del hogar: importe mensual ÷ integrantes del hogar ÷ 720 horas, por las horas de desarrollo. No es un insumo directo del sistema; su incidencia es marginal. Fuente: factura del servicio de agua.
